Workbook

Sheet 24-25雪季收入汇总
A1: 24-25雪季易龙雪聚收入汇总
A2: 总收入 | C2: ==C3+C4+C5 -> 2647931.6
A3: 租赁收入 | C3: ==C9+L9+U9 -> 820840
A4: 养护收入 | C4: ==F9+O9+X9 -> 620672
A5: 零售收入 | C5: ==I9+R9+AA9 -> 1206419.6
A6: 门店名称 | C6: 万龙店 | L6: 崇礼旗舰店 | U6: 南山店 | AD6: 儿童成长计划押金 | AE6: 儿童成长计划租金 | AF6: 客户姓名 | AG6: 收款方式
A7: 各门店收入 | C7: ==C9+F9+I9 -> 1618610.6 | L7: ==L9+O9+R9 -> 427221.01 | U7: ==U9+X9+AA9 -> 602100
A8: 业务名称 | C8: 租赁 | F8: 养护 | I8: 零售 | L8: 租赁 | O8: 养护 | R8: 零售 | U8: 租赁 | X8: 养护 | AA8: 零售
A9: 收款合计 | C9: ==SUM(C10:E15) -> 713407 | F9: ==SUM(F10:H15) -> 608042 | I9: ==SUM(I10:K15) -> 297161.6 | L9: ==SUM(L10:N15) -> 61259 | O9: ==SUM(O10:Q15) -> 2280 | R9: ==SUM(R10:T15) -> 363682.01 | U9: ==SUM(U10:W15) -> 46174 | X9: ==SUM(X10:Z15) -> 10350 | AA9: ==SUM(AA10:AC15) -> 545576 | AD9: ==SUM(AD10:AD15) -> 24260 | AE9: ==SUM(AE10:AE15) -> 4300
A10: 11月收款合计 | C10: =='24-25雪季收入明细'!C7+'24-25雪季收入明细'!D7+'24-25雪季收入明细'!E7 -> 63617 | F10: =='24-25雪季收入明细'!F7+'24-25雪季收入明细'!G7+'24-25雪季收入明细'!H7 -> 74760 | I10: =='24-25雪季收入明细'!I7+'24-25雪季收入明细'!J7+'24-25雪季收入明细'!K7 -> 5419 | L10: =='24-25雪季收入明细'!L7+'24-25雪季收入明细'!M7+'24-25雪季收入明细'!N7 -> 1460 | O10: =='24-25雪季收入明细'!O7+'24-25雪季收入明细'!P7+'24-25雪季收入明细'!Q7 -> 0 | R10: =='24-25雪季收入明细'!R7+'24-25雪季收入明细'!S7+'24-25雪季收入明细'!T7 -> 35737.01 | U10: =='24-25雪季收入明细'!U7+'24-25雪季收入明细'!V7+'24-25雪季收入明细'!W7 -> 0 | X10: =='24-25雪季收入明细'!X7+'24-25雪季收入明细'!Y7+'24-25雪季收入明细'!Z7 -> 0 | AA10: =='24-25雪季收入明细'!AA7+'24-25雪季收入明细'!AB7+'24-25雪季收入明细'!AC7+'24-25雪季收入明细'!AD7 -> 4764 | AD10: =='24-25雪季收入明细'!AE7 -> 11140 | AE10: =='24-25雪季收入明细'!AF7 -> 2300 | AF10: 陈美红 | AG10: 万龙微信4775收款
A11: 12月收款合计 | C11: =='24-25雪季收入明细'!C8+'24-25雪季收入明细'!D8+'24-25雪季收入明细'!E8 -> 236127 | F11: =='24-25雪季收入明细'!F8+'24-25雪季收入明细'!G8+'24-25雪季收入明细'!H8 -> 153180 | I11: =='24-25雪季收入明细'!I8+'24-25雪季收入明细'!J8+'24-25雪季收入明细'!K8 -> 54608.6 | L11: =='24-25雪季收入明细'!L8+'24-25雪季收入明细'!M8+'24-25雪季收入明细'!N8 -> 5430 | O11: =='24-25雪季收入明细'!O8+'24-25雪季收入明细'!P8+'24-25雪季收入明细'!Q8 -> 200 | R11: =='24-25雪季收入明细'!R8+'24-25雪季收入明细'!S8+'24-25雪季收入明细'!T8 -> 57629 | U11: =='24-25雪季收入明细'!U8+'24-25雪季收入明细'!V8+'24-25雪季收入明细'!W8 -> 6580 | X11: =='24-25雪季收入明细'!X8+'24-25雪季收入明细'!Y8+'24-25雪季收入明细'!Z8 -> 5070 | AA11: =='24-25雪季收入明细'!AA8+'24-25雪季收入明细'!AB8+'24-25雪季收入明细'!AC8+'24-25雪季收入明细'!AD8 -> 165081 | AD11: =='24-25雪季收入明细'!AE8 -> 6560 | AE11: =='24-25雪季收入明细'!AF8 -> 1000
A12: 01月收款合计 | C12: =='24-25雪季收入明细'!C9+'24-25雪季收入明细'!D9+'24-25雪季收入明细'!E9 -> 168875 | F12: =='24-25雪季收入明细'!F9+'24-25雪季收入明细'!G9+'24-25雪季收入明细'!H9 -> 135472 | I12: =='24-25雪季收入明细'!I9+'24-25雪季收入明细'!J9+'24-25雪季收入明细'!K9 -> 63554 | L12: =='24-25雪季收入明细'!L9+'24-25雪季收入明细'!M9+'24-25雪季收入明细'!N9 -> 18940 | O12: =='24-25雪季收入明细'!O9+'24-25雪季收入明细'!P9+'24-25雪季收入明细'!Q9 -> 800 | R12: =='24-25雪季收入明细'!R9+'24-25雪季收入明细'!S9+'24-25雪季收入明细'!T9 -> 105472 | U12: =='24-25雪季收入明细'!U9+'24-25雪季收入明细'!V9+'24-25雪季收入明细'!W9 -> 19824 | X12: =='24-25雪季收入明细'!X9+'24-25雪季收入明细'!Y9+'24-25雪季收入明细'!Z9 -> 3160 | AA12: =='24-25雪季收入明细'!AA9+'24-25雪季收入明细'!AB9+'24-25雪季收入明细'!AC9+'24-25雪季收入明细'!AD9 -> 230573 | AD12: =='24-25雪季收入明细'!AE9 -> 6560 | AE12: =='24-25雪季收入明细'!AF9 -> 1000
A13: 02月收款合计 | C13: =='24-25雪季收入明细'!C10+'24-25雪季收入明细'!D10+'24-25雪季收入明细'!E10 -> 138719 | F13: =='24-25雪季收入明细'!F10+'24-25雪季收入明细'!G10+'24-25雪季收入明细'!H10 -> 117155 | I13: =='24-25雪季收入明细'!I10+'24-25雪季收入明细'!J10+'24-25雪季收入明细'!K10 -> 82893 | L13: =='24-25雪季收入明细'!L10+'24-25雪季收入明细'!M10+'24-25雪季收入明细'!N10 -> 27385 | O13: =='24-25雪季收入明细'!O10+'24-25雪季收入明细'!P10+'24-25雪季收入明细'!Q10 -> 480 | R13: =='24-25雪季收入明细'!R10+'24-25雪季收入明细'!S10+'24-25雪季收入明细'!T10 -> 133184 | U13: =='24-25雪季收入明细'!U10+'24-25雪季收入明细'!V10+'24-25雪季收入明细'!W10 -> 19410 | X13: =='24-25雪季收入明细'!X10+'24-25雪季收入明细'!Y10+'24-25雪季收入明细'!Z10 -> 1720 | AA13: =='24-25雪季收入明细'!AA10+'24-25雪季收入明细'!AB10+'24-25雪季收入明细'!AC10+'24-25雪季收入明细'!AD10 -> 135457 | AD13: =='24-25雪季收入明细'!AE10 -> 0 | AE13: =='24-25雪季收入明细'!AF10 -> 0
A14: 03月收款合计 | C14: =='24-25雪季收入明细'!C11+'24-25雪季收入明细'!D11+'24-25雪季收入明细'!E11 -> 98438 | F14: =='24-25雪季收入明细'!F11 -> 110995 | I14: =='24-25雪季收入明细'!I11+'24-25雪季收入明细'!J11+'24-25雪季收入明细'!K11 -> 83051 | L14: =='24-25雪季收入明细'!L11 -> 7444 | O14: =='24-25雪季收入明细'!O11+'24-25雪季收入明细'!P11+'24-25雪季收入明细'!Q11 -> 600 | R14: =='24-25雪季收入明细'!R11+'24-25雪季收入明细'!S11+'24-25雪季收入明细'!T11 -> 30852 | U14: =='24-25雪季收入明细'!U11+'24-25雪季收入明细'!V11+'24-25雪季收入明细'!W11 -> 360 | X14: =='24-25雪季收入明细'!X11+'24-25雪季收入明细'!Y11+'24-25雪季收入明细'!Z11 -> 400 | AA14: =='24-25雪季收入明细'!AA11+'24-25雪季收入明细'!AB11+'24-25雪季收入明细'!AC11+'24-25雪季收入明细'!AD11 -> 9701 | AD14: =='24-25雪季收入明细'!AE11 -> 0 | AE14: =='24-25雪季收入明细'!AF11 -> 0
A15: 04月收款合计 | C15: =='24-25雪季收入明细'!C12+'24-25雪季收入明细'!D12+'24-25雪季收入明细'!E12 -> 7631 | F15: =='24-25雪季收入明细'!F12 -> 16480 | I15: =='24-25雪季收入明细'!I12 -> 7636 | L15: =='24-25雪季收入明细'!L12 -> 600 | O15: =='24-25雪季收入明细'!O12+'24-25雪季收入明细'!P12+'24-25雪季收入明细'!Q12 -> 200 | R15: =='24-25雪季收入明细'!R12+'24-25雪季收入明细'!S12+'24-25雪季收入明细'!T12 -> 808 | U15: =='24-25雪季收入明细'!U12+'24-25雪季收入明细'!V12+'24-25雪季收入明细'!W12 -> 0 | X15: =='24-25雪季收入明细'!X12+'24-25雪季收入明细'!Y12+'24-25雪季收入明细'!Z12 -> 0 | AA15: =='24-25雪季收入明细'!AA12+'24-25雪季收入明细'!AB12+'24-25雪季收入明细'!AC12+'24-25雪季收入明细'!AD12 -> 0 | AD15: =='24-25雪季收入明细'!AE12 -> 0 | AE15: =='24-25雪季收入明细'!AF12 -> 0
A17: 1、万龙租赁1.9客人将板丢失，押金5000做为雪板赔偿，故收入做到万龙零售中
A18: 2、旗舰零售12.17收款4200实际为南山店零售，故调出，收入做到南山店中
M20: 万龙 | N20: 0.61538462
M21: 旗舰 | N21: 0.15384615
M22: 南山 | N22: 0.23076923

Sheet 24-25雪季收入明细
A1: 24-25雪季易龙雪聚收入明细
A2: 门店名称 | C2: 万龙店 | L2: 崇礼旗舰店 | U2: 南山店
A3: 业务名称 | C3: 租赁 | F3: 养护 | I3: 零售 | L3: 租赁 | O3: 养护 | R3: 零售 | U3: 租赁 | X3: 养护 | AA3: 零售
A4: 收款方式 | C4: 微信 | D4: 京东收银 | E4: 招行 | F4: 微信 | G4: 京东收银 | H4: 招行 | I4: 微信 | J4: 京东收银 | K4: 招行 | L4: 微信 | M4: 京东收银 | N4: 招行 | O4: 微信 | P4: 京东收银 | Q4: 招行 | R4: 微信 | S4: 京东收银 | T4: 招行 | U4: 微信 | V4: 京东收银 | W4: 招行 | X4: 微信 | Y4: 京东收银 | Z4: 招行 | AA4: 微信 | AB4: 京东收银 | AC4: 招行 | AD4: 现金 | AE4: 儿童成长押金 | AF4: 儿童成长计划租金 | AG4: 客户姓名 | AH4: 收款方式
C5: 6346 | E5: 8997 | F5: 5183 | H5: 8997 | I5: 4775 | K5: 8997 | L5: 3350 | N5: 8997 | O5: 5482 | Q5: 8997 | R5: 1865 | U5: 9791 | W5: 8997 | X5: 258 | Z5: 8997 | AA5: 3448 | AC5: 8997
A6: 收款合计 | C6: ==SUM(C7:C12) -> 707857 | D6: ==SUM(D7:D12) -> 1440 | E6: ==SUM(E7:E12) -> 4110 | F6: ==SUM(F7:F12) -> 604142 | G6: ==SUM(G7:G12) -> 0 | H6: ==SUM(H7:H12) -> 3900 | I6: ==SUM(I7:I12) -> 259980.6 | J6: ==SUM(J7:J12) -> 20247 | ... AF6: ==SUM(AF7:AF12) -> 4300
A7: 11月收款合计 | C7: ==SUM(C13:C36) -> 59067 | D7: ==SUM(D13:D36) -> 1440 | E7: ==SUM(E13:E36) -> 3110 | F7: ==SUM(F13:F36) -> 74760 | G7: ==SUM(G13:G36) -> 0 | H7: ==SUM(H13:H36) -> 0 | I7: ==SUM(I13:I36) -> 5419 | J7: ==SUM(J13:J36) -> 0 | ... AF7: ==SUM(AF13:AF36) -> 2300
A8: 12月收款合计 | C8: ==SUM(C37:C67) -> 236127 | D8: ==SUM(D37:D67) -> 0 | E8: ==SUM(E37:E67) -> 0 | F8: ==SUM(F37:F67) -> 150180 | G8: ==SUM(G37:G67) -> 0 | H8: ==SUM(H37:H67) -> 3000 | I8: ==SUM(I37:I67) -> 39074.6 | J8: ==SUM(J37:J67) -> 0 | ... AF8: ==SUM(AF37:AF67) -> 1000
A9: 01月收款合计 | C9: ==SUM(C68:C98) -> 167875 | D9: ==SUM(D68:D98) -> 0 | E9: ==SUM(E68:E98) -> 1000 | F9: ==SUM(F68:F98) -> 135472 | G9: ==SUM(G68:G98) -> 0 | H9: ==SUM(H68:H98) -> 0 | I9: ==SUM(I68:I98) -> 49506 | J9: ==SUM(J68:J98) -> 14048 | ... AF9: ==SUM(AF68:AF98) -> 1000
A10: 02月收款合计 | C10: ==SUM(C99:C126) -> 138719 | D10: ==SUM(D99:D126) -> 0 | E10: ==SUM(E99:E126) -> 0 | F10: ==SUM(F99:F126) -> 116255 | G10: ==SUM(G99:G126) -> 0 | H10: ==SUM(H99:H126) -> 900 | I10: ==SUM(I99:I126) -> 76694 | J10: ==SUM(J99:J126) -> 6199 | ... AF10: ==SUM(AF99:AF126) -> 0
A11: 03月收款合计 | C11: ==SUM(C127:C157) -> 98438 | D11: ==SUM(D127:D157) -> 0 | E11: ==SUM(E127:E157) -> 0 | F11: ==SUM(F127:F157) -> 110995 | G11: ==SUM(G127:G157) -> 0 | H11: ==SUM(H127:H157) -> 0 | I11: ==SUM(I127:I157) -> 81651 | J11: ==SUM(J127:J157) -> 0 | ... AF11: ==SUM(AF127:AF157) -> 0
A12: 04月收款合计 | C12: ==SUM(C158:C177) -> 7631 | D12: ==SUM(D158:D177) -> 0 | E12: ==SUM(E158:E177) -> 0 | F12: ==SUM(F158:F177) -> 16480 | G12: ==SUM(G158:G177) -> 0 | H12: ==SUM(H158:H177) -> 0 | I12: ==SUM(I158:I177) -> 7636 | J12: ==SUM(J158:J177) -> 0 | ... AF12: ==SUM(AF158:AF177) -> 0
A13: 2024.11.07 | B13: 周四 | C13: 0 | F13: 280 | S13: 10479.01
A14: 2024.11.08 | B14: 周五 | C14: 100 | F14: 1380
A15: 2024.11.09 | B15: 周六 | C15: 3160 | F15: 4510 | I15: 790 | T15: 4650
A16: 2024.11.10 | B16: 周日 | C16: 580 | D16: 360 | F16: 3880 | N16: 1300
A17: 2024.11.11 | B17: 周一 | C17: 0 | E17: 500 | F17: 700 | AE17: 3280 | AF17: 500 | AG17: 陈美红 | AH17: 万龙零售4775收款
A18: 2024.11.12 | B18: 周二 | C18: 0 | F18: 1450
A19: 2024.11.13 | B19: 周三 | C19: 130 | F19: 1990
A20: 2024.11.14 | B20: 周四 | C20: 120 | F20: 1620 | R20: 2400
A21: 2024.11.15 | B21: 周五 | C21: 820 | F21: 2250
A22: 2024.11.16 | B22: 周六 | C22: 4431 | F22: 7310 | I22: 860
A23: 2024.11.17 | B23: 周日 | C23: 4680 | F23: 6790 | I23: 258 | L23: 160
A24: 2024.11.18 | B24: 周一 | C24: 1340 | F24: 2430 | I24: 30
A25: 2024.11.19 | B25: 周二 | C25: 1110 | F25: 1580
A26: 2024.11.20 | B26: 周三 | C26: 3040 | F26: 1050
A27: 2024.11.21 | B27: 周四 | C27: 1509 | F27: 1180
A28: 2024.11.22 | B28: 周五 | C28: 1705 | F28: 2710
A29: 2024.11.23 | B29: 周六 | C29: 4690 | D29: 1080 | E29: 610 | F29: 7010 | I29: 588 | T29: 2244
A30: 2024.11.24 | B30: 周日 | C30: 3111 | E30: 500 | F30: 5140 | R30: 445 | AE30: 3280 | AF30: 500 | AG30: 王婧婧 | AH30: 万龙零售4775收款
A31: 2024.11.25 | B31: 周一 | C31: 3390 | F31: 2130 | I31: 146 | T31: 4100
A32: 2024.11.26 | B32: 周二 | C32: 2370 | F32: 4320
A33: 2024.11.27 | B33: 周三 | C33: 300 | F33: 2570
A34: 2024.11.28 | B34: 周四 | C34: ==2965-720 -> 2245 | F34: 1910 | R34: 3080 | AC34: 474
A35: 2024.11.29 | B35: 周五 | C35: 2961 | F35: 2200 | I35: 1732
A36: 2024.11.30 | B36: 周六 | C36: 17275 | E36: 1500 | F36: 8370 | I36: 1015 | R36: 1180 | T36: 7159 | AD36: 4290 | AE36: 4580 | AF36: 1300 | AG36: 李聪 | AH36: 万龙零售4775收款
A37: 2024.12.01 | B37: 周日 | C37: 11487 | F37: 4390 | I37: 784
A38: 2024.12.02 | B38: 周一 | C38: 5070 | F38: 3150 | I38: 1201 | K38: 359 | R38: 1180
A39: 2024.12.03 | B39: 周二 | C39: 3650 | F39: 3320 | I39: 289
A40: 2024.12.04 | B40: 周三 | C40: 2010 | F40: 3260 | I40: 336
...

Sheet 万龙租赁
C1: 业务门店 | D1: 开单门店 | E1: 订单ID | F1: 门店 | G1: 姓名 | H1: 电话 | I1: 押金 | J1: 退款 | K1: 结余 | L1: 损坏赔偿 | M1: 租金 | N1: 支付方式 | O1: 日期 | P1: 时间 | Q1: 接待 | R1: 员工
A2: 1 | B2: 系统订单 | C2: 万龙 | D2: 万龙 | E2: 4798 | F2: 万龙体验中心 | G2: 肖志强（个人） 先生 | H2: 15838200977 | I2: 100 | J2: 0 | K2: 100 | L2: 0 | M2: 100 | N2: 微信支付 | O2: 45605 | P2: 0.86050926 | Q2: 肖志强（工作号） | R2: 肖志强
A3: 2 | B3: 系统订单 | C3: 万龙 | D3: 万龙 | E3: 4801 | F3: 万龙体验中心 | H3: 13488805747 | I3: 4400 | J3: 3845 | K3: 555 | L3: 0 | M3: 555 | N3: 微信支付 | O3: 45605 | P3: 0.6884375 | Q3: 肖志强（工作号） | R3: 肖志强
B4: 系统订单 | C4: 万龙 | D4: 万龙 | E4: 4802 | F4: 万龙体验中心 | G4: 张 先生 | H4: 13810012539 | I4: 3000 | J4: 2850 | K4: 150 | L4: 0 | M4: 150 | N4: 微信支付 | O4: 45605 | P4: 0.85915509 | Q4: 肖志强（工作号） | R4: 肖志强
B5: 系统订单 | C5: 万龙 | D5: 万龙 | E5: 4803 | F5: 万龙体验中心 | G5: 王 女士 | H5: 15933571552 | I5: 1000 | J5: 900 | K5: 100 | L5: 0 | M5: 100 | N5: 微信支付 | O5: 45605 | P5: 0.51715278 | Q5: 肖志强（工作号） | R5: 肖志强
B6: 系统订单 | C6: 万龙 | D6: 万龙 | E6: 4804 | F6: 万龙体验中心 | G6: 边 女士 | H6: 18622485396 | I6: 5000 | J6: 4520 | K6: 480 | L6: 0 | M6: 480 | N6: 微信支付 | O6: 45605 | P6: 0.71063657 | Q6: 肖志强（工作号） | R6: 肖志强
B7: 系统订单 | C7: 万龙 | D7: 万龙 | E7: 4807 | F7: 万龙体验中心 | G7: 贾 女士 | H7: 13911055600 | I7: 3000 | J7: 2820 | K7: 180 | L7: 0 | M7: 180 | N7: 微信支付 | O7: 45606 | P7: 0.37611111 | Q7: 修姜山（个人） | R7: 修姜山
B8: 系统订单 | C8: 万龙 | D8: 万龙 | E8: 4808 | F8: 万龙体验中心 | G8: 胡 女士 | H8: 13601008796 | I8: 1000 | J8: 880 | K8: 120 | L8: 0 | M8: 120 | N8: 微信支付 | O8: 45605 | P8: 0.78667824 | Q8: 修姜山（个人） | R8: 修姜山
B9: 系统订单 | C9: 万龙 | D9: 万龙 | E9: 4811 | F9: 万龙体验中心 | G9: 郑 先生 | H9: 18920043297 | I9: 4000 | J9: 3580 | K9: 420 | L9: 0 | M9: 420 | N9: 微信支付 | O9: 45605 | P9: 0.66454861 | Q9: 肖志强（工作号） | R9: 肖志强
B10: 系统订单 | C10: 万龙 | D10: 万龙 | E10: 4812 | F10: 万龙体验中心 | G10: 孟 先生 | H10: 16620464110 | I10: 5000 | J10: 3930 | K10: 1070 | L10: 0 | M10: 1070 | N10: 微信支付 | O10: 45605 | P10: 0.72135417 | Q10: 修姜山（个人） | R10: 修姜山
B11: 系统订单 | C11: 万龙 | D11: 万龙 | E11: 4813 | F11: 万龙体验中心 | G11: 范 先生 | H11: 15133330377 | I11: 1000 | J11: 945 | K11: 55 | L11: 0 | M11: 55 | N11: 微信支付 | O11: 45605 | P11: 0.87210648 | Q11: 肖志强（工作号） | R11: 肖志强
B12: 系统订单 | C12: 万龙 | D12: 万龙 | E12: 4814 | F12: 万龙体验中心 | G12: 赵 先生 | H12: 18034018073 | I12: 5000 | J12: 4790 | K12: 210 | L12: 0 | M12: 210 | N12: 微信支付 | O12: 45605 | P12: 0.88186343 | Q12: 肖志强（工作号） | R12: 肖志强
B13: 系统订单 | C13: 万龙 | D13: 万龙 | E13: 4815 | F13: 万龙体验中心 | G13: 倪 先生 | H13: 15001130086 | I13: 3000 | J13: 2820 | K13: 180 | L13: 0 | M13: 180 | N13: 微信支付 | O13: 45606 | P13: 0.50959491 | Q13: 肖志强（工作号） | R13: 肖志强
B14: 系统订单 | C14: 万龙 | D14: 万龙 | E14: 4816 | F14: 万龙体验中心 | G14: 先生 | H14: 18941347398 | I14: 5000 | J14: 4780 | K14: 220 | L14: 0 | M14: 220 | N14: 微信支付 | O14: 45606 | P14: 0.60344907 | Q14: 肖志强（工作号） | R14: 肖志强
B15: 系统订单 | C15: 万龙 | D15: 万龙 | E15: 4819 | F15: 万龙体验中心 | G15: 刘 先生 | H15: 17610855261 | I15: 200 | J15: 170 | K15: 30 | L15: 0 | M15: 30 | N15: 微信支付 | O15: 45609 | P15: 0.66787037 | Q15: 肖志强（工作号） | R15: 肖志强
... B111: 系统订单 | C111: 万龙 | D111: 万龙 | E111: 4951 | F111: 万龙体验中心 | G111: 陆 先生 | H111: 13910839831 | I111: 200 | J111: 150 | K111: 50 | L111: 0 | M111: 50 | N111: 微信支付 | O111: 45618 | P111: 0.66090278 | Q111: 张小飞 | R111: 张小飞
B112: 人工订单 | D112: 万龙 | E112: 【-】 | F112: 万龙体验中心 | G112: 【-】 | H112: 【-】 | I112: 【-】 | J112: 【-】 | K112: 【-】 | L112: 【-】 | M112: 610 | N112: 崔洋（微信） | O112: 45619 | P112: 【-】 | Q112: 崔洋 | R112: 崔洋
B113: 系统订单 | C113: 万龙 | D113: 万龙 | E113: 4952 | F113: 万龙体验中心 | G113: 王 先生 | H113: 13911285423 | I113: 5000 | J113: 4780 | K113: 220 | L113: 0 | M113: 220 | N113: 微信支付 | O113: 45619 | P113: 0.6747338 | Q113: 肖志强（工作号） | R113: 肖志强
B114: 系统订单 | C114: 万龙 | D114: 万龙 | E114: 4953 | F114: 万龙体验中心 | G114: 黄 女士 | H114: 13510860612 | I114: 1000 | J114: 760 | K114: 240 | L114: 0 | M114: 240 | N114: 微信支付 | O114: 45620 | P114: 0.61574074 | Q114: 许进升（个人） | R114: 许进升
B115: 系统订单 | C115: 万龙 | D115: 万龙 | E115: 4954 | F115: 万龙体验中心 | G115: 汪 先生 | H115: 13683137883 | I115: 8000 | J115: 7800 | K115: 200 | L115: 0 | M115: 200 | N115: 微信支付 | O115: 45619 | P115: 0.67327546 | Q115: 张 | R115: 张亮
B116: 系统订单 | C116: 万龙 | D116: 万龙 | E116: 4955 | F116: 万龙体验中心 | G116: 张 先生 | H116: 15864669981 | I116: 3000 | J116: 2640 | K116: 360 | L116: 0 | M116: 360 | N116: 微信支付 | O116: 45620 | P116: 0.51989583 | Q116: 肖志强（工作号） | R116: 肖志强
B117: 系统订单 | C117: 万龙 | D117: 万龙 | E117: 4956 | F117: 万龙体验中心 | G117: 33 女士 | H117: 15901402678 | I117: 3000 | J117: 2850 | K117: 150 | L117: 0 | M117: 150 | N117: 微信支付 | O117: 45619 | P117: 0.60678241 | Q117: 肖志强（工作号） | R117: 肖志强
B118: 系统订单 | C118: 万龙 | D118: 万龙 | E118: 4957 | F118: 万龙体验中心 | G118: 龚 女士 | H118: 18258157160 | I118: 1000 | J118: 760 | K118: 240 | L118: 0 | M118: 240 | N118: 微信支付 | O118: 45619 | P118: 0.49493056 | Q118: 肖志强（工作号） | R118: 肖志强
B119: 系统订单 | C119: 万龙 | D119: 万龙 | E119: 4958 | F119: 万龙体验中心 | G119: 魏 女士 | H119: 13510660342 | I119: 1000 | J119: 860 | K119: 140 | L119: 0 | M119: 140 | N119: 微信支付 | O119: 45619 | P119: 0.65559028 | Q119: 张小飞 | R119: 张小飞
B120: 系统订单 | C120: 万龙 | D120: 万龙 | E120: 4959 | F120: 万龙体验中心 | G120: 陈 女士 | H120: 18678419009 | I120: 200 | J120: 140 | K120: 60 | L120: 0 | M120: 60 | N120: 微信支付 | O120: 45619 | P120: 0.6871875 | Q120: 肖志强（工作号） | R120: 肖志强
B121: 系统订单 | C121: 万龙 | D121: 万龙 | E121: 4960 | F121: 万龙体验中心 | G121: 王 先生 | H121: 18618151709 | I121: 500 | J121: 380 | K121: 120 | L121: 0 | M121: 120 | N121: 微信支付 | O121: 45619 | P121: 0.7965162 | Q121: 修姜山（个人） | R121: 修姜山
B122: 系统订单 | C122: 万龙 | D122: 万龙 | E122: 4961 | F122: 万龙体验中心 | G122: 孙 先生 | H122: 13466365627 | I122: 3500 | J122: 3230 | K122: 270 | L122: 0 | M122: 270 | N122: 微信支付 | O122: 45619 | P122: 0.66791667 | Q122: 张小飞 | R122: 张小飞
B123: 系统订单 | C123: 万龙 | D123: 万龙 | E123: 4962 | F123: 万龙体验中心 | G123: 袁 先生 | H123: 13926153716 | I123: 2800 | J123: 2440 | K123: 360 | L123: 0 | M123: 360 | N123: 微信支付 | O123: 45619 | P123: 0.58991898 | Q123: 鲁延盼（个人） | R123: 鲁延盼
B124: 系统订单 | C124: 万龙 | D124: 万龙 | E124: 4963 | F124: 万龙体验中心 | G124: 吴 女士 | H124: 18322703739 | I124: 200 | J124: 200 | K124: 0 | L124: 0 | M124: 0 | N124: 微信支付 | O124: 45619 | P124: 0.51774306 | Q124: 鲁延盼（个人） | R124: 鲁延盼
... B130: 系统订单 | C130: 万龙 | D130: 万龙 | E130: 4971 | F130: 万龙体验中心 | G130: 沈 女士 | H130: 13522755246 | I130: 3000 | J130: 2870 | K130: 130 | L130: 0 | M130: 130 | N130: 微信支付 | O130: 45619 | P130: 0.66469907 | Q130: 王政（个人） | R130: 王政
B131: 系统订单 | C131: 万龙 | D131: 万龙 | E131: 4972 | F131: 万龙体验中心 | G131: 崔 女士 | H131: 15028333199 | I131: 1000 | J131: 880 | K131: 120 | L131: 0 | M131: 120 | N131: 微信支付 | O131: 45619 | P131: 0.57304398 | Q131: 肖志强（工作号） | R131: 肖志强 | S131: 61117
B132: 系统订单 | C132: 万龙 | D132: 万龙 | E132: 4973 | F132: 万龙体验中心 | G132: 毕 女士 | H132: 13264376996 | I132: 3000 | J132: 2820 | K132: 180 | L132: 0 | M132: 180 | N132: 微信支付 | O132: 45619 | P132: 0.68400463 | Q132: 许进升（个人） | R132: 许进升 | S132: 60147
B133: 系统订单 | C133: 万龙 | D133: 万龙 | E133: 4974 | F133: 万龙体验中心 | G133: 王 先生 | H133: 18511266606 | I133: 3000 | J133: 2490 | K133: 510 | L133: 0 | M133: 510 | N133: 微信支付 | O133: 45620 | P133: 0.65547454 | Q133: 肖志强（工作号） | R133: 肖志强 | S133: ==S131-S132 -> 970
B134: 系统订单 | C134: 万龙 | D134: 万龙 | E134: 4975 | F134: 万龙体验中心 | G134: 焦教练 先生 | H134: 18846049897 | I134: 200 | J134: 200 | K134: 0 | L134: 0 | M134: 0 | N134: 微信支付 | O134: 45619 | P134: 0.58065972 | Q134: 肖志强（工作号） | R134: 肖志强
B135: 系统订单 | C135: 万龙 | D135: 万龙 | E135: 4976 | F135: 万龙体验中心 | G135: 徐 先生 | H135: 13461035455 | I135: 5500 | J135: 5130 | K135: 370 | L135: 0 | M135: 370 | N135: 微信支付 | O135: 45619 | P135: 0.66722222 | Q135: 张小飞 | R135: 张小飞
B136: 系统订单 | C136: 万龙 | D136: 万龙 | E136: 4977 | F136: 万龙体验中心 | G136: 郭 先生 | H136: 13810355958 | I136: 1000 | J136: 880 | K136: 120 | L136: 0 | M136: 120 | N136: 微信支付 | O136: 45619 | P136: 0.70693287 | Q136: 肖志强（工作号） | R136: 肖志强
B137: 系统订单 | C137: 万龙 | D137: 万龙 | E137: 4978 | F137: 万龙体验中心 | G137: 高 先生 | H137: 17736520626 | I137: 1000 | J137: 920 | K137: 80 | L137: 0 | M137: 80 | N137: 微信支付 | O137: 45619 | P137: 0.6409375 | Q137: 肖志强（工作号） | R137: 肖志强
B138: 系统订单 | C138: 万龙 | D138: 万龙 | E138: 4979 | F138: 万龙体验中心 | G138: 张 女士 | H138: 13178258227 | I138: 200 | J138: 150 | K138: 50 | L138: 0 | M138: 50 | N138: 微信支付 | O138: 45619 | P138: 0.69318287 | Q138: 修姜山（个人） | R138: 修姜山
B139: 系统订单 | C139: 万龙 | D139: 万龙 | E139: 4980 | F139: 万龙体验中心 | G139: 叶 女士 | H139: 18813075146 | I139: 3000 | J139: 2260 | K139: 740 | L139: 0 | M139: 740 | O139: 45619 | P139: 0.74555556 | Q139: 张小飞（个人） | R139: 张小飞
B140: 系统订单 | C140: 万龙 | D140: 万龙 | E140: 4981 | F140: 万龙体验中心 | G140: 孙先生（个人） 先生 | H140: 13070943844 | I140: 7500 | J140: 6280 | K140: 1220 | L140: 0 | M140: 1220 | O140: 45620 | P140: 0.67061343 | Q140: 韩冬垚（个人） | R140: 韩冬垚
...

Sheet 旗舰租赁
A1: 订单ID | B1: 门店 | C1: 姓名 | D1: 电话 | E1: 押金 | F1: 退款 | G1: 结余 | H1: 损坏赔偿 | I1: 租金 | J1: 支付方式 | K1: 日期 | L1: 时间 | M1: 接待
A2: 4831 | B2: 崇礼旗舰店 | C2: 段 先生 | D2: 18614055589 | E2: 3000 | F2: 2840 | G2: 160 | H2: 0 | I2: 160 | J2: 微信支付 | K2: 45613 | L2: 0.8084838 | M2: 崔洋（个人）
A3: 5350 | B3: 崇礼旗舰店 | C3: 徐 先生 | D3: 15198919768 | E3: 400 | F3: 320 | G3: 80 | H3: 0 | I3: 80 | K3: 45634 | L3: 0.58872685 | M3: 姜山（工作号）
A4: 5397 | B4: 崇礼旗舰店 | C4: 张 先生 | D4: 18611380822 | E4: 3000 | F4: 2700 | G4: 300 | H4: 0 | I4: 300 | K4: 45637 | L4: 0.50078704 | M4: 白雪景（工作号）
A5: 5417 | B5: 崇礼旗舰店 | C5: 崔 先生 | D5: 13357737705 | E5: 6000 | F5: 4900 | G5: 1100 | H5: 0 | I5: 1100 | K5: 45646 | L5: 0.71668981 | M5: 肖志强（工作号）
A6: 5436 | B6: 崇礼旗舰店 | C6: 李哥 先生 | D6: 13581616818 | E6: 3000 | F6: 3000 | G6: 0 | H6: 0 | I6: 0 | K6: 45637 | L6: 0.48346065 | M6: 姜山（工作号）
A7: 5454 | B7: 崇礼旗舰店 | C7: 魏 先生 | D7: 13323031637 | E7: 2500 | F7: 2150 | G7: 350 | H7: 0 | I7: 350 | K7: 45642 | L7: 0.4124537 | M7: 姜山（工作号）
A8: 5701 | B8: 崇礼旗舰店 | C8: 胡 先生 | D8: 15001229880 | E8: 2000 | F8: 1760 | G8: 240 | H8: 0 | I8: 240 | K8: 45648 | L8: 0.71395833 | M8: 肖志强（工作号）
A9: 5705 | B9: 崇礼旗舰店 | C9: 曹 女士 | D9: 13811145027 | E9: 12000 | F9: 11540 | G9: 460 | H9: 0 | I9: 460 | K9: 45648 | L9: 0.77423611 | M9: 姜山（工作号）
A10: 5707 | B10: 崇礼旗舰店 | C10: 王一顺 先生 | D10: 18001263600 | E10: 3780 | F10: 0 | G10: 3780 | H10: 0 | I10: 3780 | K10: 45650 | L10: 0.46759259 | M10: 姜山（工作号）
A11: 5774 | B11: 崇礼旗舰店 | C11: 于洋 先生 | D11: 15810752278 | E11: 3000 | F11: 2900 | G11: 100 | H11: 0 | I11: 100 | K11: 45648 | L11: 0.53292824 | M11: 姜山（工作号）
A12: 5783 | B12: 崇礼旗舰店 | C12: 杨 先生 | D12: 13002386145 | E12: 5000 | F12: 3650 | G12: 1350 | H12: 0 | I12: 1350 | K12: 45656 | L12: 0.59790509 | M12: 姜山（工作号）
A13: 5965 | B13: 崇礼旗舰店 | C13: 王 女士 | D13: 13810103141 | E13: 8000 | F13: 7700 | G13: 300 | H13: 0 | I13: 300 | K13: 45654 | L13: 0.69934028 | M13: 姜山（工作号）
A14: 6021 | B14: 崇礼旗舰店 | C14: 张 先生 | D14: 13161872447 | E14: 1000 | F14: 0 | G14: 1000 | H14: 0 | I14: 900 | J14: 现金 | K14: 45658 | L14: 0.67986111 | M14: 崔洋（个人）
A15: 6037 | B15: 崇礼旗舰店 | C15: 张浩 先生 | D15: 13663235345 | E15: 3000 | F15: 2250 | G15: 750 | H15: 0 | I15: 750 | K15: 45659 | L15: 0.78086806 | M15: 姜山（工作号）
A16: 6102 | B16: 崇礼旗舰店 | C16: 王 先生 | D16: 18518021266 | E16: 4500 | F16: 4350 | G16: 150 | H16: 0 | I16: 150 | K16: 45656 | L16: 0.59400463 | M16: 张凯
A17: 6103 | B17: 崇礼旗舰店 | C17: 郭 女士 | D17: 18666290357 | E17: 9000 | F17: 8460 | G17: 540 | H17: 0 | I17: 540 | K17: 45658 | L17: 0.36126157 | M17: 崔洋（个人）
A18: 6131 | B18: 崇礼旗舰店 | C18: 赵 女士 | D18: 18618237080 | E18: 3000 | F18: 2800 | G18: 200 | H18: 0 | I18: 200 | K18: 45658 | L18: 0.54975694 | M18: 韩冬垚
A19: 6155 | B19: 崇礼旗舰店 | C19: 张浩 先生 | D19: 13663235345 | E19: 3000 | F19: 2400 | G19: 600 | H19: 0 | I19: 600 | K19: 45661 | L19: 0.83329861 | M19: 姜山（工作号）
A20: 6176 | B20: 崇礼旗舰店 | C20: 丁丁 女士 | D20: 15921485281 | E20: 5000 | F20: 4400 | G20: 600 | H20: 0 | I20: 600 | K20: 45661 | L20: 0.87024306 | M20: 姜山（工作号）
A21: 6177 | B21: 崇礼旗舰店 | C21: 陈 女士 | D21: 13524724162 | E21: 3000 | F21: 2820 | G21: 180 | H21: 0 | I21: 180 | K21: 45661 | L21: 0.87135417 | M21: 姜山（工作号）
A22: 6191 | B22: 崇礼旗舰店 | C22: 王 先生 | D22: 18519119280 | E22: 5000 | F22: 4700 | G22: 300 | H22: 0 | I22: 300 | K22: 45662 | L22: 0.69733796 | M22: 姜山（工作号）
A23: 6212 | B23: 崇礼旗舰店 | C23: 刘 先生 | D23: 18611616181 | E23: 3000 | F23: 2740 | G23: 260 | H23: 0 | I23: 260 | K23: 45662 | L23: 0.63516204 | M23: 姜山（工作号）
A24: 6214 | B24: 崇礼旗舰店 | C24: 张 先生 | D24: 15647775777 | E24: 6000 | F24: 5760 | G24: 240 | H24: 0 | I24: 240 | K24: 45664 | L24: 0.41541667 | M24: 姜山（工作号）
A25: 6225 | B25: 崇礼旗舰店 | C25: 孙 先生 | D25: 15602131444 | E25: 4000 | F25: 3600 | G25: 400 | H25: 0 | I25: 400 | K25: 45662 | L25: 0.71466435 | M25: 张凯（工作）
A26: 6345 | B26: 崇礼旗舰店 | C26: 张 女士 | D26: 18734136185 | E26: 5200 | F26: 4920 | G26: 280 | H26: 0 | I26: 280 | K26: 45663 | L26: 0.72829861 | M26: 姜山（工作号）
... A61: 8028 | B61: 崇礼旗舰店 | C61: 王 先生 | D61: 13910814974 | E61: 11000 | F61: 10620 | G61: 380 | H61: 0 | I61: 380 | K61: 45688 | L61: 0.75177083 | M61: 姜山（工作号）

Sheet 南山租赁
A1: 订单ID | B1: 门店 | C1: 姓名 | D1: 电话 | E1: 押金 | F1: 退款 | G1: 结余 | H1: 损坏赔偿 | I1: 租金 | J1: 支付方式 | K1: 日期 | L1: 时间 | M1: 接待
A2: 5466 | B2: 南山 | C2: 王 女士 | D2: 18500557654 | E2: 300 | F2: 220 | G2: 80 | H2: 0 | I2: 80 | K2: 45638 | L2: 0.91570602 | M2: 孙亚先（个人）
A3: 5500 | B3: 南山 | C3: 杨 女士 | D3: 13801234117 | E3: 5000 | F3: 4850 | G3: 150 | H3: 0 | I3: 75 | K3: 45640 | L3: 0.69530093 | M3: 张新健
A4: 5532 | B4: 南山 | C4: 阮 女士 | D4: 18612441206 | E4: 300 | F4: 250 | G4: 50 | H4: 0 | I4: 50 | K4: 45640 | L4: 0.68665509 | M4: 孙亚先（个人）
A5: 5583 | B5: 南山 | C5: 李 女士 | D5: 18810793067 | E5: 300 | F5: 240 | G5: 60 | H5: 0 | I5: 30 | K5: 45641 | L5: 0.86107639 | M5: 孙亚先（个人）
A6: 5596 | B6: 南山 | C6: 先生 | D6: 13621077659 | E6: 3000 | F6: 2800 | G6: 200 | H6: 0 | I6: 200 | K6: 45641 | L6: 0.72863426 | M6: 孙亚先（个人）
A7: 5630 | B7: 南山 | C7: 刘 先生 | D7: 18519890880 | E7: 200 | F7: 170 | G7: 30 | H7: 0 | I7: 30 | K7: 45642 | L7: 0.89711806 | M7: 孙亚先（个人）
A8: 5675 | B8: 南山 | C8: 张 先生 | D8: 13911461009 | E8: 600 | F8: 450 | G8: 150 | H8: 0 | I8: 75 | K8: 45645 | L8: 0.68017361 | M8: 孙亚先（个人）
A9: 5703 | B9: 南山 | C9: 1 先生 | D9: 13581809847 | E9: 200 | F9: 170 | G9: 30 | H9: 0 | I9: 30 | K9: 45646 | L9: 0.89909722 | M9: 孙亚先（个人）
A10: 5739 | B10: 南山 | C10: 张 女士 | D10: 13810852246 | E10: 1000 | F10: 880 | G10: 120 | H10: 0 | I10: 120 | K10: 45647 | L10: 0.73878472 | M10: 孙亚先（个人）
A11: 5785 | B11: 南山 | C11: 刘 先生 | D11: 13910524531 | E11: 5000 | F11: 4600 | G11: 400 | H11: 0 | I11: 400 | K11: 45647 | L11: 0.92333333 | M11: 孙亚先（个人）
A12: 5788 | B12: 南山 | C12: 王倩 女士 | D12: 18228644679 | E12: 30 | F12: 0 | G12: 30 | H12: 0 | I12: 30 | K12: 45647 | L12: 0.83635417 | M12: 孙亚先（个人）
A13: 5802 | B13: 南山 | C13: 胡 先生 | D13: 15160025952 | E13: 200 | F13: 160 | G13: 40 | H13: 0 | I13: 40 | K13: 45648 | L13: 0.57892361 | M13: 张新健
... A39: 6154 | B39: 南山 | C39: 蔡 先生 | D39: 13860718782 | E39: 6000 | F39: 5720 | G39: 280 | H39: 0 | I39: 280 | K39: 45657 | L39: 0.83783565 | M39: 张新健
A40: 5881 | B40: 南山 | C40: 王 女士 | D40: 15268360035 | E40: 80 | F40: 0 | G40: 80 | H40: 0 | I40: 80 | K40: 45673 | L40: 0.66427083 | M40: 王倩 | N40: 此订单租金为80
A41: 6167 | B41: 南山 | C41: 王 先生 | D41: 13811598328 | E41: 5000 | F41: 5000 | G41: 0 | H41: 0 | I41: 0 | K41: 45658 | L41: 0.58311343 | M41: 张新健
A42: 6175 | B42: 南山 | C42: 孔 先生 | D42: 15697842637 | E42: 3000 | F42: 2760 | G42: 240 | H42: 0 | I42: 240 | K42: 45658 | L42: 0.92145833 | M42: 孙亚先（个人）
A43: 6188 | B43: 南山 | C43: 邓 女士 | D43: 15652093999 | E43: 3000 | F43: 2880 | G43: 120 | H43: 0 | I43: 120 | K43: 45659 | L43: 0.90428241 | M43: 王倩
A44: 6246 | B44: 南山 | C44: 赵旻鹏 先生 | D44: 13821177163 | E44: 2000 | F44: 1880 | G44: 120 | H44: 0 | I44: 120 | K44: 45661 | L44: 0.71747685 | M44: 张新健
A45: 6249 | B45: 南山 | C45: 赵 先生 | D45: 18210238697 | E45: 600 | F45: 520 | G45: 80 | H45: 0 | I45: 80 | K45: 45661 | L45: 0.64953704 | M45: 孙亚先（个人）
A46: 6271 | B46: 南山 | C46: 俞 先生 | D46: 13701681552 | E46: 10000 | F46: 9540 | G46: 460 | H46: 0 | I46: 460 | K46: 45661 | L46: 0.87943287 | M46: 张新健
A47: 6287 | B47: 南山 | C47: 杨 先生 | D47: 15100678165 | E47: 7000 | F47: 6440 | G47: 560 | H47: 0 | I47: 560 | K47: 45661 | L47: 0.87818287 | M47: 孙亚先（个人）
A48: 6316 | B48: 南山 | C48: 邱 女士 | D48: 18552254527 | E48: 3000 | F48: 2880 | G48: 120 | H48: 0 | I48: 120 | K48: 45662 | L48: 0.72413194 | M48: 孙亚先（个人）
A49: 6337 | B49: 南山 | C49: 叶 女士 | D49: 15077408044 | E49: 3000 | F49: 2880 | G49: 120 | H49: 0 | I49: 120 | K49: 45662 | L49: 0.62234954 | M49: 孙亚先（个人）
A50: 6369 | B50: 南山 | C50: 徐 先生 | D50: 18101254910 | E50: 600 | F50: 520 | G50: 80 | H50: 0 | I50: 80 | K50: 45664 | L50: 0.7047338 | M50: 孙亚先（个人）
A51: 6377 | B51: 南山 | C51: 徐 先生 | D51: 17600834429 | E51: 200 | F51: 170 | G51: 30 | H51: 0 | I51: 30 | K51: 45664 | L51: 0.71868056 | M51: 张新健
A52: 6393 | B52: 南山 | C52: 关 先生 | D52: 13121928108 | E52: 121 | F52: 1 | G52: 120 | H52: 0 | I52: 120 | K52: 45665 | L52: 0.67960648 | M52: 张新健
... A82: 6612 | B82: 南山 | C82: 赵 先生 | D82: 13701256865 | E82: 5000 | F82: 4850 | G82: 150 | H82: 0 | I82: 150 | K82: 45673 | L82: 0.62446759 | M82: 张新健
A83: 6616 | B83: 南山 | C83: 张新健 先生 | D83: 18612472341 | E83: 460 | F83: 0 | G83: 460 | H83: 0 | I83: 460 | J83: 现金 | K83: 45673 | L83: 0.48877315 | M83: 张新健
A84: 6620 | B84: 南山 | C84: 李 女士 | D84: 19818321219 | E84: 300 | F84: 260 | G84: 40 | H84: 0 | I84: 40 | K84: 45673 | L84: 0.8696875 | M84: 孙亚先（个人）
A85: 6621 | B85: 南山 | C85: 安 女士 | D85: 13329363952 | E85: 1000 | F85: 900 | G85: 100 | H85: 0 | I85: 100 | K85: 45673 | L85: 0.93425926 | M85: 孙亚先（个人）
A86: 6629 | B86: 南山 | C86: 杨 女士 | D86: 18604886880 | E86: 8000 | F86: 7630 | G86: 370 | H86: 0 | I86: 370 | K86: 45674 | L86: 0.70803241 | M86: 张新健
A87: 6630 | B87: 南山 | C87: 罗 女士 | D87: 18179143711 | E87: 3000 | F87: 2920 | G87: 80 | H87: 0 | I87: 80 | K87: 45682 | L87: 0.56457176 | M87: 张新健
A88: 6641 | B88: 南山 | C88: 俞 先生 | D88: 13701681552 | E88: 3000 | F88: 2470 | G88: 530 | H88: 0 | I88: 530 | K88: 45674 | L88: 0.89797454 | M88: 孙亚先（个人）
A89: 6648 | B89: 南山 | C89: 王倩 女士 | D89: 18228644679 | E89: 121 | F89: 1 | G89: 120 | H89: 0 | I89: 120 | K89: 45674 | L89: 0.93800926 | M89: 王倩
A90: 6685 | B90: 南山 | C90: 杨 女士 | D90: 18301069131 | E90: 500 | F90: 380 | G90: 120 | H90: 0 | I90: 120 | K90: 45675 | L90: 0.59622685 | M90: 王倩
A91: 6688 | B91: 南山 | C91: 刘 先生 | D91: 18249100567 | E91: 5000 | F91: 4850 | G91: 150 | H91: 0 | I91: 150 | K91: 45675 | L91: 0.92549769 | M91: 张新健
A92: 6694 | B92: 南山 | C92: 俞 先生 | D92: 13701681552 | E92: 2000 | F92: 1700 | G92: 300 | H92: 0 | I92: 300 | K92: 45675 | L92: 0.70971065 | M92: 孙亚先（个人）
A93: 6698 | B93: 南山 | C93: 李 先生 | D93: 15831600748 | E93: 200 | F93: 170 | G93: 30 | H93: 0 | I93: 30 | K93: 45675 | L93: 0.66015046 | M93: 张新健
A94: 6704 | B94: 南山 | C94: 刘梓宸 先生 | D94: 15901371387 | E94: 201 | F94: 1 | G94: 200 | H94: 0 | I94: 200 | K94: 45675 | L94: 0.74517361 | M94: 张新健
...

Sheet 养护日报表
A1: 养护收入
A2: 门店 | B2: 流水号 | C2: 类型 | D2: 品牌 | E2: 长度 | F2: 角度 | G2: 修刃 | H2: 打蜡 | I2: 刮蜡 | J2: 其它 | K2: 备注 | L2: 维修技师 | M2: 附加费用 | N2: 接待 | O2: 日期 | P2: 时间 | Q2: 订单号 | R2: 金额
A3: 万龙服务中心 | B3: 241130-00048 | C3: 单板 | D3: Gray | E3: 148 | F3: 0 | G3: -- | H3: -- | I3: -- | J3: 其它,粘板面 | L3: (个人)张亮 | M3: 200 | N3: (个人)张亮 | O3: 45626 | P3: 0.89967593 | Q3: 41452 | R3: 200
A4: 万龙服务中心 | B4: 241130-00047 | C4: 双板 | D4: Ogasaka/小贺 | E4: 165 | F4: 0 | G4: -- | H4: (个人)张亮 | I4: (个人)张亮 | L4: -- | M4: 0 | N4: (个人)张亮 | O4: 45626 | P4: 0.85368056 | Q4: 41449 | R4: 150
A5: 万龙服务中心 | B5: 241130-00046 | C5: 单板 | D5: Gray | E5: 160 | F5: 0 | G5: -- | H5: 王政 | I5: 王政 | K5: 800元机打蜡卡消费 | L5: -- | M5: 0 | N5: (个人)王政 | O5: 45626 | P5: 0.75611111 | Q5: 0 | R5: 0
A6: 万龙服务中心 | B6: 241130-00045 | C6: 单板 | D6: Burton | E6: 153 | F6: 89 | G6: (个人)张亮 | H6: -- | I6: -- | J6: 其它 | K6: 2付板 | L6: (个人)张亮 | M6: 150 | N6: (个人)张亮 | O6: 45626 | P6: 0.72325231 | Q6: 41437 | R6: 300
A7: 万龙服务中心 | B7: 241130-00044 | C7: 双板 | D7: Volkl/沃克 | E7: 165 | F7: 0 | G7: -- | H7: -- | I7: -- | J7: 其它,粘板面 | L7: (个人)张亮 | M7: 100 | N7: (个人)张亮 | O7: 45626 | P7: 0.72188657 | Q7: 41436 | R7: 100
A8: 万龙服务中心 | B8: 241130-00043 | C8: 单板 | D8: 未知品牌/未知品牌 | E8: 140 | F8: 0 | G8: -- | H8: -- | I8: -- | J8: 粘板面 | L8: (个人)张亮 | M8: 200 | N8: 王政 | O8: 45626 | P8: 0.71025463 | Q8: 41435 | R8: 200
A9: 万龙服务中心 | B9: 241130-00042 | C9: 单板 | D9: 未知品牌/未知品牌 | E9: 165 | F9: 0 | G9: -- | H9: (个人)张亮 | I9: (个人)张亮 | L9: -- | M9: 0 | N9: (个人)张亮 | O9: 45626 | P9: 0.70548611 | Q9: 41433 | R9: 150
A10: 万龙服务中心 | B10: 241130-00041 | C10: 单板 | D10: Gray | E10: 170 | F10: 89 | G10: 张亮 | H10: 张亮 | I10: 张亮 | J10: 其它,粘板面 | L10: 张亮 | M10: 100 | N10: 张亮 | O10: 45626 | P10: 0.70438657 | Q10: 41432 | R10: 330
A11: 万龙服务中心 | B11: 241130-00040 | C11: 双板 | D11: Ogasaka/小贺 | E11: 165 | F11: 89 | G11: 王政 | H11: 王政 | I11: 王政 | L11: -- | M11: 0 | N11: 王政 | O11: 45626 | P11: 0.70128472 | Q11: 41431 | R11: 430
A12: 万龙服务中心 | B12: 241130-00039 | C12: 单板 | D12: Jones | E12: 155 | F12: 89 | G12: (个人)张亮 | H12: (个人)张亮 | I12: (个人)张亮 | L12: -- | M12: 0 | N12: 王政 | O12: 45626 | P12: 0.70034722
A13: 万龙服务中心 | B13: 241130-00038 | C13: 双板 | D13: Rossignol/金鸡 | E13: 157 | F13: 89 | G13: 王政 | H13: 王政 | I13: 王政 | L13: -- | M13: 0 | N13: 王政 | O13: 45626 | P13: 0.69173611 | Q13: 41430 | R13: 200
A14: 万龙服务中心 | B14: 241130-00037 | C14: 单板 | D14: 未知品牌/未知品牌 | E14: 150 | F14: 0 | G14: -- | H14: 王政 | I14: 王政 | L14: -- | M14: 0 | N14: 王政 | O14: 45626 | P14: 0.68127315 | Q14: 41429 | R14: 150
A15: 万龙服务中心 | B15: 241130-00036 | C15: 单板 | D15: 未知品牌/未知品牌 | E15: 155 | F15: 89 | G15: 张亮 | H15: 张亮 | I15: 张亮 | L15: -- | M15: 0 | N15: 王政 | O15: 45626 | P15: 0.67743056 | Q15: 41428 | R15: 230
A16: 万龙服务中心 | B16: 241130-00035 | C16: 单板 | D16: 未知品牌/未知品牌 | E16: 145 | F16: 0 | G16: -- | H16: 张亮 | I16: 张亮 | L16: -- | M16: 0 | N16: 张亮 | O16: 45626 | P16: 0.6693287 | Q16: 41427 | R16: 150
A17: 万龙服务中心 | B17: 241130-00034 | C17: 单板 | D17: Capita | E17: 150 | F17: 0 | G17: -- | H17: -- | I17: -- | J17: 粘板面,其它 | L17: 张亮 | M17: 100 | N17: 张亮 | O17: 45626 | P17: 0.65969907 | Q17: 41425 | R17: 100
A18: 万龙服务中心 | B18: 241130-00033 | C18: 双板 | D18: Faction | E18: 183 | F18: 0 | G18: -- | H18: 张亮 | I18: 张亮 | J18: 其它,补板底 | L18: 张亮 | M18: 100 | N18: 张亮 | O18: 45626 | P18: 0.65363426 | Q18: 41424 | R18: 270
A19: 万龙服务中心 | B19: 241130-00032 | C19: 单板 | D19: 未知品牌/未知品牌 | E19: 150 | F19: 89 | G19: 张亮 | H19: 张亮 | I19: 张亮 | L19: -- | M19: 0 | N19: 王政 | O19: 45626 | P19: 0.65148148 | Q19: 41423 | R19: 230
B20: 241130-00031 | C20: 双板 | D20: Volkl/沃克 | E20: 165 | F20: 87 | G20: -- | H20: -- | I20: -- | L20: -- | M20: 0 | N20: 张亮 | O20: 45626 | P20: 0.65056713 | Q20: 0 | R20: 0
A21: 万龙服务中心 | B21: 241130-00030 | C21: 双板 | D21: Volkl/沃克 | E21: 160 | F21: 88 | G21: 王政 | H21: 王政 | I21: 王政 | L21: -- | M21: 0 | N21: 张亮 | O21: 45626 | P21: 0.62155093 | Q21: 41420 | R21: 200
A22: 万龙服务中心 | B22: 241130-00029 | C22: 双板 | D22: Dynastar | E22: 162 | F22: 88 | G22: 王政 | H22: 王政 | I22: 王政 | L22: -- | M22: 0 | N22: 张亮 | O22: 45626 | P22: 0.61414352 | Q22: 41419 | R22: 200
A23: 万龙服务中心 | B23: 241130-00028 | C23: 单板 | D23: 未知品牌/未知品牌 | E23: 150 | F23: 0 | G23: -- | H23: -- | I23: -- | J23: 螺丝 | L23: 王政 | M23: 50 | N23: 王政 | O23: 45626 | P23: 0.6103588 | Q23: 41418 | R23: 50
A24: 万龙服务中心 | B24: 241130-00027 | C24: 双板 | D24: Fischer/费舍尔 | E24: 150 | F24: 88 | G24: 王政 | H24: -- | I24: -- | L24: -- | M24: 0 | N24: 张亮 | O24: 45626 | P24: 0.60677083 | Q24: 41416 | R24: 170
A25: 万龙服务中心 | B25: 241130-00026 | C25: 双板 | D25: Kessler | E25: 165 | F25: 88 | G25: 王政 | H25: -- | I25: -- | L25: -- | M25: 0 | N25: 王政 | O25: 45626 | P25: 0.60537037 | Q25: 41414 | R25: 150
A26: 万龙服务中心 | B26: 241130-00025 | C26: 单板 | D26: Burton | E26: 150 | F26: 0 | G26: -- | H26: 王政 | I26: 王政 | L26: -- | M26: 0 | N26: 王政 | O26: 45626 | P26: 0.59791667 | Q26: 41413 | R26: 170
A27: 万龙服务中心 | B27: 241130-00024 | C27: 单板 | D27: 未知品牌/未知品牌 | E27: 150 | F27: 0 | G27: -- | H27: 王政 | I27: 王政 | L27: -- | M27: 0 | N27: 王政 | O27: 45626 | P27: 0.59314815 | Q27: 41409 | R27: 170
A28: 万龙服务中心 | B28: 241130-00023 | C28: 双板 | D28: Head/海德 | E28: 165 | F28: 88 | G28: 张亮 | H28: -- | I28: -- | L28: -- | M28: 0 | N28: 张亮 | O28: 45626 | P28: 0.57115741 | Q28: 41407 | R28: 170
A29: 万龙服务中心 | B29: 241130-00022 | C29: 双板 | D29: Head/海德 | E29: 155 | F29: 89 | G29: -- | H29: -- | I29: -- | L29: -- | M29: 0 | N29: 张亮 | O29: 45626 | P29: 0.55364583 | Q29: 41401 | R29: 230
A30: 万龙服务中心 | B30: 241130-00021 | C30: 双板 | D30: Stockli/斯托克林 | E30: 165 | F30: 88 | G30: 王政 | H30: -- | I30: -- | L30: -- | M30: 0 | N30: 张亮 | O30: 45626 | P30: 0.52203704 | Q30: 41385 | R30: 170
A31: 万龙服务中心 | B31: 241130-00020 | C31: 双板 | D31: Fischer/费舍尔 | E31: 178 | F31: 87 | G31: 王政 | H31: 王政 | I31: 王政 | L31: -- | M31: 0 | N31: 张亮 | O31: 45626 | P31: 0.51486111 | Q31: 41380 | R31: 230
A32: 万龙服务中心 | B32: 241130-00019 | C32: 单板 | D32: Burton | E32: 157 | F32: 0 | G32: -- | H32: 张亮 | I32: 张亮 | L32: -- | M32: 0 | N32: 张亮 | O32: 45626 | P32: 0.51295139 | Q32: 41379 | R32: 150
A33: 万龙服务中心 | B33: 241130-00018 | C33: 双板 | D33: Ogasaka/小贺 | E33: 165 | F33: 88 | G33: 张亮 | H33: 张亮 | I33: 张亮 | L33: -- | M33: 0 | N33: 张亮 | O33: 45626 | P33: 0.50542824 | Q33: 41322 | R33: 200
A34: 万龙服务中心 | B34: 241130-00017 | C34: 单板 | D34: 未知品牌/未知品牌 | E34: 150 | F34: 0 | G34: -- | H34: 张亮 | I34: 张亮 | L34: -- | M34: 0 | N34: 张亮 | O34: 45626 | P34: 0.48871528 | Q34: 41318 | R34: 170
A35: 万龙服务中心 | B35: 241130-00016 | C35: 单板 | D35: Capita | E35: 165 | F35: 0 | G35: -- | H35: 张亮 | I35: 张亮 | L35: -- | M35: 0 | N35: 王政 | O35: 45626 | P35: 0.48408565 | Q35: 41316 | R35: 170
A36: 万龙服务中心 | B36: 241130-00015 | C36: 双板 | D36: Volkl/沃克 | E36: 165 | F36: 89 | G36: 王政 | H36: 王政 | I36: 王政 | L36: -- | M36: 0 | N36: 王政 | O36: 45626 | P36: 0.47818287 | Q36: 41314 | R36: 230
A37: 万龙服务中心 | B37: 241130-00014 | C37: 双板 | D37: Head/海德 | E37: 165 | F37: 0 | G37: -- | H37: -- | I37: -- | J37: 双板固定器 | L37: 张亮 | M37: 200 | N37: 王政 | O37: 45626 | P37: 0.4721412 | Q37: 41311 | R37: 200
A38: 万龙服务中心 | B38: 241130-00013 | C38: 单板 | D38: Gray | E38: 150 | F38: 0 | G38: -- | H38: -- | I38: -- | J38: 其它 | K38: 安固定器 | L38: 王政 | M38: 50 | N38: 王政 | O38: 45626 | P38: 0.46298611 | Q38: 41307 | R38: 50
A39: 万龙服务中心 | B39: 241130-00012 | C39: 单板 | D39: 未知品牌/未知品牌 | E39: 155 | F39: 0 | G39: -- | H39: -- | I39: -- | J39: 其它,螺丝 | L39: 张亮 | M39: 50 | N39: 张亮 | O39: 45626 | P39: 0.46238426 | Q39: 41305 | R39: 50
A40: 万龙服务中心 | B40: 241130-00011 | C40: 单板 | D40: 未知品牌/未知品牌 | E40: 150 | F40: 0 | G40: -- | H40: -- | I40: -- | J40: 其它,绑带 | L40: 张亮 | M40: 130 | N40: 张亮 | O40: 45626 | P40: 0.41085648 | Q40: 41283 | R40: 130
...

Sheet 七色米零售报表
A1: 业务日期 | B1: 单据编号 | C1: 所属门店 | D1: 仓库 | E1: 总计金额 | F1: 实收金额 | G1: 特殊情况 | H1: 结算方式 | I1: 经手人 | J1: 备注
A2: 45598 | B2: XSD20241114000I | C2: 【崇礼】【旗舰店】 | D2: 【旗舰】零售商品仓 | E2: 320 | F2: 320 | H2: 京东收银-ZB | I2: 旗舰王政
A3: 45599 | B3: XSD20241103000I | C3: 【总部】 | D3: 【旗舰】零售商品仓 | E3: 389 | F3: 389 | H3: 京东收银-ZB | I3: 【总部】布乖
A4: 45603 | B4: XSD20241107000 | C4: 【崇礼】【旗舰店】 | D4: 【旗舰】零售商品仓 | E4: 8070 | F4: 8070 | H4: 京东收银-ZB | I4: 【旗舰】布乖
A5: 45605 | B5: XSD20241109001I | C5: 【总部】 | D5: 【旗舰】零售商品仓 | E5: 4650 | F5: 4650 | G5: 11.22提现8997 | H5: 现金-ZB | I5: 【总部】布乖
A6: 45605 | B6: XSD20241109000I | C6: 【总部】 | D6: 【万龙体验】零售商品仓 | E6: 790 | F6: 790 | H6: 【小程序】微信-ZB | I6: 【总部】布乖
A7: 45606 | B7: XSD20241110002I | C7: 【总部】 | D7: 【万龙体验】零售商品仓 | E7: 96 | F7: 0 | G7: 未收款 | H7: 现金-ZB | I7: 【总部】布乖 | J7: 等雪服调换完后一起结账
A8: 45606 | B8: XSD20241110001I | C8: 【总部】 | D8: 【旗舰】零售商品仓 | E8: 0 | F8: 0 | H8: 银行转账-ZB | I8: 【总部】布乖 | J8: 赠送
A9: 45606 | B9: XSD20241110000I | C9: 【总部】 | D9: 【旗舰】租赁试滑仓 | E9: 1300 | F9: 1300 | G9: 11.22提现8997 | H9: 现金-ZB | I9: 【总部】布乖
A10: 45607 | B10: XSD20241111000A | C10: 【崇礼】【万龙店】 | D10: 【万龙体验】租赁试滑仓 | E10: 3780 | F10: 3780 | H10: 【小程序】微信-WL | I10: 【万龙】肖志强 | J10: 儿童成长计划 小程序单号40676
A11: 45610 | B11: XSD20241117001A | C11: 【崇礼】【旗舰店】 | D11: 【旗舰】零售商品仓 | E11: 2400 | F11: 2400 | H11: 【小程序】微信-QJ | I11: 旗舰_修姜山 | J11: 富龙教练 订单号:40729
A12: 45612 | B12: XSD20241116003A | C12: 【崇礼】【万龙店】 | D12: 【万龙体验】零售商品仓 | E12: 199 | F12: 200 | G12: 现金在店长手里 | H12: 现金-WL | I12: 【万龙】肖志强 | J12: 定单号40825
A13: 45612 | B13: XSD20241116002A | C13: 【崇礼】【万龙店】 | D13: 【万龙体验】零售商品仓 | E13: 558 | F13: 558 | H13: 【小程序】微信-WL | I13: 【万龙】肖志强 | J13: 定单号40787
A14: 45612 | B14: XSD20241116001A | C14: 【崇礼】【万龙店】 | D14: 【万龙体验】零售商品仓 | E14: 116 | F14: 116 | H14: 【小程序】微信-WL | I14: 【万龙】肖志强 | J14: 订单号40780
A15: 45612 | B15: XSD20241116000A | C15: 【崇礼】【万龙店】 | D15: 【万龙体验】零售商品仓 | E15: 128 | F15: 128 | H15: 【小程序】微信-WL | I15: 【万龙】肖志强 | J15: 订单号40752
A16: 45613 | B16: XSD20241117002A | C16: 【崇礼】【万龙店】 | D16: 【万龙体验】零售商品仓 | E16: 149 | F16: 149 | H16: 【小程序】微信-WL | I16: 万龙_张小飞 | J16: 订单号40888
A17: 45613 | B17: XSD20241117000A | C17: 【崇礼】【万龙店】 | D17: 【万龙体验】零售商品仓 | E17: 109 | F17: 109 | H17: 【小程序】微信-WL | I17: 万龙_张小飞 | J17: 订单号40857
A18: 45614 | B18: XSD20241118000A | C18: 【崇礼】【万龙店】 | D18: 【万龙体验】零售商品仓 | E18: 30 | F18: 30 | H18: 【小程序】微信-WL | I18: 【万龙】肖志强 | J18: 订单号40923
A19: 45616 | B19: XSD20241120000A | C19: 【崇礼】【万龙店】 | D19: 【万龙体验】零售商品仓 | E19: 0 | F19: 0 | H19: 【小程序】微信-WL | I19: 【万龙】肖志强 | J19: 崔洋招待 孙亚先
A20: 45617 | B20: XSD20241121000I | C20: 【总部】 | D20: 【旗舰】零售商品仓 | E20: 0 | F20: 0 | H20: 银行转账-ZB | I20: 【总部】布乖 | J20: 杨总
A21: 45618 | B21: XSD20241122000I | C21: 【总部】 | D21: 【旗舰】零售商品仓 | E21: 12572.45 | F21: 0 | H21: 银行转账-ZB | I21: 【总部】布乖
A22: 45619 | B22: XSD20241123006I | C22: 【崇礼】【万龙店】 | D22: 【万龙体验】零售商品仓 | E22: 359 | F22: 359 | G22: 微信4775收款 | H22: 【小程序】微信-ZB | I22: 万龙_修姜山 | J22: 雪蜡
A23: 45619 | B23: XSD20241123004I | C23: 【总部】 | D23: 【旗舰】零售商品仓 | E23: 1809.5 | F23: 1809.5 | G23: 11.23提现8997 | H23: 银行转账-ZB | I23: 公司管理员
A24: 45619 | B24: XSD20241123005I | C24: 【总部】 | D24: 【旗舰】零售商品仓 | E24: 434.5 | F24: 434.5 | G24: 11.23提现8997 | H24: 银行转账-ZB | I24: 【总部】布乖
A25: 45619 | B25: XSD20241123002I | C25: 【总部】 | D25: 【旗舰】零售商品仓 | E25: 3299.45 | F25: 0 | H25: 银行转账-ZB | I25: 【总部】布乖
A26: 45619 | B26: XSD20241123001A | C26: 【崇礼】【万龙店】 | D26: 【万龙体验】零售商品仓 | E26: 199 | F26: 199 | G26: 微信4775收款 | H26: 【小程序】微信-WL | I26: 万龙_张小飞 | J26: 41014
A27: 45619 | B27: XSD20241123000A | C27: 【崇礼】【万龙店】 | D27: 【万龙体验】零售商品仓 | E27: 30 | F27: 30 | G27: 微信4775收款 | H27: 【小程序】微信-WL | I27: 【万龙】肖志强 | J27: 订单号：41005
A28: 45620 | B28: XSD20241124001A | C28: 【崇礼】【万龙店】 | D28: 【万龙体验】租赁试滑仓 | E28: 3780 | F28: 3780 | G28: 微信4775收款 | H28: 【小程序】微信-WL | I28: 【万龙】肖志强 | J28: 儿童成长计划 小程序订单号：41111
A29: 45620 | B29: XSD20241124000I | C29: 【总部】 | D29: 【旗舰】零售商品仓 | E29: 445 | F29: 445 | G29: 微信1865收款 | H29: 【小程序】微信-ZB | I29: 公司管理员 | J29: 小程序41098
A30: 45621 | B30: XSD20241125003A | C30: 【崇礼】【万龙店】 | D30: 【万龙体验】零售商品仓 | E30: 30 | F30: 30 | G30: 微信4775收款 | H30: 【小程序】微信-WL | I30: 【万龙】肖志强 | J30: 小程序订单号：41155
A31: 45621 | B31: XSD20241125002A | C31: 【崇礼】【万龙店】 | D31: 【万龙体验】零售商品仓 | E31: 58 | F31: 58 | G31: 微信4775收款 | H31: 【小程序】微信-WL | I31: 【万龙】肖志强 | J31: 小程序订单号：41154
A32: 45621 | B32: XSD20241125001I | C32: 【总部】 | D32: 【旗舰】零售商品仓 | E32: 4100 | F32: 4100 | G32: 11.25提现8997 | H32: 银行转账-ZB | I32: 【总部】布乖 | J32: 批发业务
A33: 45621 | B33: XSD20241125000A | C33: 【崇礼】【万龙店】 | D33: 【万龙体验】零售商品仓 | E33: 58 | F33: 58 | G33: 微信4775收款 | H33: 【小程序】微信-WL | I33: 【万龙】肖志强 | J33: 小程序订单号：41139
A34: 45622 | B34: XSD20241126000I | C34: 【崇礼】【万龙店】 | D34: 【万龙体验】零售商品仓 | E34: 359 | F34: 359 | G34: 银行转账-ZB | H34: 张凯微信收款转布乖微信 提现8997 | I34: 万龙_张凯 | J34: 雪蜡12.2收款
A35: 45624 | B35: XSD20241128000A | C35: 【北京】【南山店】 | D35: 【总部】崇礼新景家园固定资产仓 | E35: 474 | F35: 474 | G35: 11.28提现8997 | H35: 现金-NS | I35: 南山店员02
A36: 45625 | B36: XSD20241129001A | C36: 【崇礼】【万龙店】 | D36: 【万龙体验】零售商品仓 | E36: 174 | F36: 174 | G36: 微信4775收款 | H36: 【小程序】微信-WL | I36: 【万龙】肖志强 | J36: 订单号：41218
A37: 45625 | B37: XSD20241129000A | C37: 【崇礼】【万龙店】 | D37: 【万龙体验】零售商品仓 | E37: 58 | F37: 58 | G37: 微信4775收款 | H37: 【小程序】微信-WL | I37: 万龙_张小飞 | J37: 41216
A38: 45626 | B38: XSD20241130006I | C38: 【崇礼】【万龙店】 | D38: 【万龙体验】零售商品仓 | E38: 359 | F38: 359 | G38: 微信4775收款 | H38: 【小程序】微信-ZB | I38: 万龙_修姜山 | J38: 雪蜡
A39: 45626 | B39: XSD20241130005I | C39: 【总部】 | D39: 【万龙体验】租赁试滑仓 | E39: 6080 | F39: 6080 | G39: 微信4775收款 | H39: 【小程序】微信-ZB | I39: 【总部】布乖
A40: 45626 | B40: XSD20241130004I | C40: 【崇礼】【旗舰店】 | D40: 【旗舰】零售商品仓 | E40: 7159 | F40: 7159 | G40: 11.30提现8997 | H40: 微信转账-LX | I40: 【旗舰】舒武新 | J40: 发快递试号 微信转布乖 提现8997
...

Sheet 备忘录
B1: 租赁收入 | F1: 雪蜡销售 | K1: 崇礼公司现金收入
A2: 2024.11.24 | B2: 1080 | C2: 支付宝收款 | D2: 苍杰报表中没有这两笔订单 | F2: 日期 | G2: 金额 | H2: 收款方式 | I2: 提现时间
A3: 2024.11.23 | B3: 610 | C3: 崔洋个人微信收款 | F3: 2024.11.23 | G3: 359 | H3: 微信4775
F4: 2024.11.26 | G4: 359 | H4: 8997提现 | I4: 12.6 | K4: 45605 | L4: XSD20241109001I | M4: 【总部】 | N4: 4650 | O4: 8997提现 | P4: 11.22提现
F5: 2024.11.30 | G5: 259 | H5: 微信4775 | K5: 45606 | L5: XSD20241110000I | M5: 【旗舰】租赁收入 | N5: 1300 | O5: 8997提现 | P5: 11.22提现
F6: 2024.11.30 | G6: 359 | H6: 微信4775 | K6: 45612 | L6: XSD20241116003A | M6: 【崇礼】【万龙店】 | N6: 200 | O6: 现金 | P6: 给崔洋了
F7: 2024.12.7 | G7: 359 | H7: 微信4775 | K7: 45619 | L7: XSD20241123004I | M7: 【总部】 | N7: 1809.5 | O7: 8997提现 | P7: 11.23提现
F8: 2024.12.8 | G8: 359 | H8: 8997提现 | I8: 12.12 | K8: 45619 | L8: XSD20241123005I | M8: 【总部】 | N8: 434.5 | O8: 8997提现 | P8: 11.23提现
F9: 2024.12.8 | G9: 359 | H9: 8997提现 | I9: 12.12 | K9: 45621 | L9: XSD20241125001I | M9: 【总部】 | N9: 4100 | P9: 11.25提现
A10: 特殊事项 | F10: 2024.12.15 | G10: 149 | H10: 微信4775 | K10: 45622 | L10: XSD20241126000I | M10: 【崇礼】【万龙店】 | N10: 359 | P10: 12.2提现
A11: 2025.1.9 | B11: 5000 | C11: 租赁客人丢失雪板，押金全部赔偿雪板，做到万龙体验中心零售收入中 | F11: 2024.12.15 | G11: 359 | H11: 微信4775 | K11: 45624 | L11: XSD20241128000A | M11: 【北京】【南山店】 | N11: 474 | O11: 8997提现 | P11: 11.28提现
F12: 2024.12.15 | G12: 359 | H12: 微信4775 | K12: 45626 | L12: XSD20241130004I | M12: 【崇礼】【旗舰店】 | N12: 7159 | O12: 8997提现 | P12: 11.30提现
F13: 2024.12.18 | G13: 359 | H13: 8997提现 | K13: 45619 | M13: 南山雪票款 | N13: 610 | O13: 现金
F14: 2024.12.21 | G14: 299 | H14: 微信4775 | K14: 45631 | L14: XSD20241205005 | M14: 【总部】 | N14: 300 | O14: 8997提现 | P14: 12.5提现
F15: 2024.12.22 | G15: 299 | H15: 微信4775 | K15: 45633 | L15: XSD20241207024I | M15: 【总部】 | N15: 400 | O15: 8997提现 | P15: 12.7提现
F16: 2024.12.23 | G16: 359 | H16: 微信3448 | K16: 45637 | L16: XSD20241211008A | M16: 【北京】【南山店】 | N16: 560 | O16: 8997提现 | P16: 12.12提现
F17: 2024.12.28 | G17: 359 | H17: 微信4775 | K17: 45640 | L17: XSD20241214027I | M17: 【崇礼】【万龙店】 | N17: 180 | O17: 8997提现 | P17: 12.12提现 | Q17: 补差
F18: 2024.12.29 | G18: 259 | H18: 微信4775 | K18: 45641 | L18: XSD20241215013I | M18: 【崇礼】【万龙店】 | N18: 359 | O18: 现金 | P18: 4.15提现
F19: 2024.12.29 | G19: 259 | H19: 微信4775 | K19: 45641 | L19: XSD20241215012I | M19: 【崇礼】【万龙店】 | N19: 359 | O19: 现金 | P19: 4.15提现
F20: 2024.12.31 | G20: 259 | H20: 京东收银 | K20: 45644 | L20: XSD20241218013I | M20: 【崇礼】【旗舰店】 | N20: 359 | P20: 布乖
F21: 2025.1.3 | G21: 359 | H21: 微信4775 | K21: 45644 | M21: 万龙体验中心 | N21: 1500 | O21: 8997提现 | P21: 1.19提现
F22: 2025.1.4 | G22: 359 | K22: 45648 | L22: XSD20241222011I | M22: 【崇礼】【旗舰店】 | N22: 6300 | O22: 8997提现 | P22: 12.22提现
F23: 2025.1.4 | G23: 259 | K23: 45648 | L23: XSD20241222022I | M23: 【崇礼】【万龙店】 | N23: 13200 | O23: 8997提现 | P23: 12.22提现
F24: 2025.1.4 | G24: 259 | K24: 45651 | L24: XSD20241225001I | M24: 【崇礼】【旗舰店】 | N24: 1500 | O24: 现金 | P24: 布乖 | Q24: 崔洋开单
F25: 2025.1.5 | G25: 359 | K25: 45652 | L25: XSD20241226003I | M25: 【崇礼】【旗舰店】 | N25: 1000 | O25: 现金 | P25: 4.15提现
F26: 2025.1.5 | G26: 359 | K26: 45676 | L26: XSD20250119011I | M26: 【崇礼】【旗舰店】 | N26: 1670 | O26: 8997提现 | P26: 1.19提现
F27: 2025.1.11 | G27: 259 | K27: 45691 | L27: XSD20250203016I | M27: 【崇礼】【旗舰店】 | N27: 4300 | O27: 8997提现 | P27: 2.6提现
F28: 2025.1.12 | G28: 259 | K28: 45694 | L28: XSD20250206025I | M28: 【总部】 | N28: 4700 | O28: 8997提现 | P28: 2.6提现
F29: 2025.1.12 | G29: 259 | K29: 45697 | L29: XSD20250209017I | M29: 【崇礼】【旗舰店】 | N29: 796 | O29: 现金 | P29: 4.15提现
F30: 2025.1.12 | G30: 259 | K30: 45697 | L30: XSD20250208011I | M30: 公司管理员 | N30: 759 | O30: 现金 | P30: 4.15提现
F31: 2025.1.19 | G31: 259 | K31: 45704 | L31: XSD20250216000I | M31: 【总部】布乖 | N31: 4900 | O31: 8997 | P31: 2.15提现
K32: 45689 | L32: XSD20250201037I | M32: 【总部】 | N32: 800 | O32: 银行转账-ZB | P32: 2.1提现
K33: 45689 | L33: XSD20250201029I | M33: 【崇礼】【旗舰店】 | N33: 100 | O33: 现金 | P33: 4.15提现
K34: 45699 | L34: XSD20250211009I | M34: 【总部】布乖 | N34: 4900 | O34: 8997 | P34: 2.11提现
K35: 45713 | L35: XSD20250225004I | M35: 【总部】布乖 | N35: 4700 | O35: 银行转账-ZB
C36: 南山现金收入 | K36: 45729 | L36: XSD20250312000 | M36: 【总部】 | N36: 560 | O36: 银行转账-ZB
C37: 45626 | D37: XSD20241130003A | E37: 【北京】【南山店】 | F37: 4290 | G37: 现金 | K37: 45732 | L37: XSD20250316004 | M37: 【崇礼】【万龙店】 | N37: 1400 | O37: 银行转账 | P37: 2025.4.11
C38: 45633 | D38: XSD20241207017A | E38: 【北京】【南山店】 | F38: 300 | G38: 现金 | N38: 760
C39: 45633 | D39: XSD20241207011A | E39: 【北京】【南山店】 | F39: 480 | G39: 现金
C40: 45633 | D40: XSD20241207010A | E40: 【北京】【南山店】 | F40: 4400 | G40: 现金
...

Sheet 小程序零售报表
A1: 日期 | B1: 七色米订单号 | C1: 商品条码 | D1: 市场价 | E1: 成交价 | F1: 订单号 | G1: 门店 | H1: 姓名 | I1: 电话 | J1: 订单金额（标粉色为七色米未做单） | K1: 调整金额（与七色米对比） | L1: 时间 | M1: 收款方式 | N1: 销售 | O1: 备注
J2: 此两项合计金额为到账金额
A3: 45747 | B3: XSD20241114000I | D3: 858 | E3: 320 | F3: 54082 | G3: 崇礼旗舰店 | J3: 320 | L3: 0.77758102 | M3: 京东收银 | N3: 布乖（个人） | O3: 补2024.11.14订单
A4: 45603 | B4: XSD20241107000 | D4: 14180 | E4: 8070 | F4: 40585 | G4: 崇礼旗舰店 | H4: 吕原野先生 | I4: 17542913333 | J4: 8070 | K4: 0 | L4: 0.94638889 | M4: 京东收银 | N4: 布乖
A5: 45605 | B5: XSD20241109001I | D5: 6344 | E5: 4650 | F5: 40640 | G5: 崇礼旗舰店 | H5: 高嵩先生 | J5: 4650 | K5: 0 | L5: 0.92086806 | M5: 现金 | N5: 布乖
A6: 45605 | B6: null | D6: 1490 | E6: 790 | F6: 40635 | G6: 万龙体验中心 | H6: 霍先生 | I6: 13901273805 | J6: 790 | K6: 0 | L6: 0.7675463 | M6: 微信支付 | N6: 布乖
A7: 45607 | B7: 紧急开单 | D7: 3780 | E7: 3780 | F7: 40676 | G7: 万龙体验中心 | H7: 陈美红女士 | I7: 13510110412 | J7: 3780 | K7: 0 | L7: 0.56416667 | M7: 微信支付 | N7: 肖志强
A8: 45610 | B8: 紧急开单 | D8: 3999 | E8: 2400 | F8: 40729 | G8: 崇礼旗舰店 | H8: 崔杰女士 | I8: 19213045200 | J8: 2400 | K8: 0 | L8: 0.8271412 | M8: 微信支付 | O8: 富龙教练，6折
A9: 45610 | B9: XSD20241114000 | D9: 698 | E9: 320 | F9: 40718 | G9: 崇礼旗舰店 | H9: 孙天时先生 | I9: 13839011338 | J9: 320 | K9: 0 | L9: 0.45260417 | M9: 京东收银 | N9: 布乖 | O9: 实际订单日期2024.11.2
A10: 45610 | B10: XSD20241103000I | D10: 398 | E10: 398 | F10: 40717 | G10: 崇礼旗舰店 | H10: 一尘女士 | J10: 398 | K10: -9 | L10: 0.445625 | M10: 京东收银 | N10: 布乖 | O10: 实际业务日期2024.11.3
A11: 45610 | B11: XSD20241109001I | D11: 6344 | E11: 4650 | F11: 40716 | G11: 崇礼旗舰店 | H11: 高嵩先生 | J11: 4650 | L11: 0.44478009 | M11: 现金 | N11: 布乖 | O11: 实际订单日期2024.11.9
A12: 45610 | B12: XSD20241110000I | D12: 1500 | E12: 1300 | F12: 40715 | G12: 崇礼旗舰店 | H12: 高嵩先生 | J12: 1300 | K12: 0 | L12: 0.44292824 | M12: 现金 | N12: 布乖 | O12: 业务实际日期2024.11.10
A13: 45612 | B13: 紧急开单 | D13: 58 | E13: 58 | F13: 40844 | G13: 万龙体验中心 | H13: 崔洋 | I13: 13910231129 | J13: 58 | L13: 0.85055556 | M13: 微信支付 | N13: 崔洋
A14: 45612 | B14: null | D14: 200 | E14: 200 | F14: 40825 | G14: 万龙体验中心 | H14: 肖志强（个人）先生 | I14: 18612317853 | J14: 200 | L14: 0.67675926 | M14: 现金 | N14: 肖志强
A15: 45612 | B15: 紧急开单 | D15: 558 | E15: 558 | F15: 40787 | G15: 万龙体验中心 | H15: 肖志强（个人）先生 | I15: 18612317853 | J15: 558 | L15: 0.67189815 | M15: 微信支付 | N15: 肖志强
A16: 45612 | B16: 紧急开单 | D16: 116 | E16: 116 | F16: 40780 | G16: 万龙体验中心 | H16: 宗佳女士 | I16: 19932327706 | J16: 116 | L16: 0.47974537 | M16: 微信支付 | N16: 肖志强
A17: 45612 | B17: 紧急开单 | D17: 128 | E17: 128 | F17: 40752 | G17: 万龙体验中心 | H17: 肖志强 | I17: 18612317853 | J17: 128 | L17: 0.34902778 | M17: 微信支付 | N17: 肖志强
A18: 45613 | B18: 紧急开单 | D18: 149 | E18: 149 | F18: 40888 | G18: 万龙体验中心 | H18: 朱女士 | I18: 18018592806 | J18: 149 | L18: 0.70641204 | M18: 微信支付 | N18: (个人)张小飞
A19: 45613 | B19: 紧急开单 | D19: 109 | E19: 109 | F19: 40857 | G19: 万龙体验中心 | H19: 付 | I19: 15635172829 | J19: 109 | L19: 0.46241898 | M19: 微信支付 | N19: (个人)张小飞
A20: 45614 | B20: null | D20: 30 | E20: 30 | F20: 40923 | G20: 万龙体验中心 | H20: 肖志强（个人）先生 | I20: 18612317853 | J20: 30 | L20: 0.76173611 | M20: 微信支付 | N20: 肖志强
A21: 45619 | B21: XSD20241123004I | D21: 3950 | E21: 1809.5 | F21: 41080 | G21: 崇礼旗舰店 | H21: 赵文广先生 | J21: 1809.5 | L21: 0.90758102 | M21: 现金 | N21: 布乖 | O21: 银行转账
A22: 45619 | B22: XSD20241123005I | D22: 790 | E22: 434.5 | F22: 41079 | G22: 崇礼旗舰店 | H22: 赵文广先生 | J22: 434.5 | L22: 0.90662037 | M22: 现金 | N22: 布乖
A23: 45619 | B23: null | D23: 399 | E23: 359 | F23: 41068 | G23: 万龙体验中心 | H23: 张骞先生 | I23: 13693547369 | J23: 359 | L23: 0.74362269 | M23: 微信支付 | N23: 布乖
A24: 45619 | B24: 紧急开单 | D24: 199 | E24: 199 | F24: 41014 | G24: 万龙体验中心 | J24: 199 | L24: 0.42001157 | M24: 微信支付 | N24: (个人)张小飞
A25: 45619 | B25: null | D25: 30 | E25: 30 | F25: 41005 | G25: 万龙体验中心 | H25: 先生 | I25: 18610492765 | J25: 30 | L25: 0.38728009 | M25: 微信支付 | N25: 肖志强
A26: 45620 | B26: null | D26: 3780 | E26: 3780 | F26: 41111 | G26: 万龙体验中心 | H26: 王婧婧女士 | I26: 15357199988 | J26: 3780 | L26: 0.5940162 | M26: 微信支付 | N26: 肖志强 | O26: 儿童成长计划
A27: 45620 | B27: null | D27: 890 | E27: 445 | F27: 41098 | G27: 崇礼旗舰店 | H27: 姜楠女士 | I27: 15210988580 | J27: 445 | L27: 0.51644676 | M27: 微信支付 | N27: 布乖
G28: 崇礼旗舰店 | J28: 0 | K28: 4100 | M28: 提现8997 | N28: 布乖 | O28: 布乖
A29: 45621 | B29: null | D29: 30 | E29: 30 | F29: 41155 | G29: 万龙体验中心 | H29: 朱先生 | I29: 15635261688 | J29: 30 | L29: 0.79612269 | M29: 微信支付 | N29: 肖志强
A30: 45621 | B30: null | D30: 58 | E30: 58 | F30: 41154 | G30: 万龙体验中心 | H30: 郝先生 | I30: 17660406631 | J30: 58 | L30: 0.78623843 | M30: 微信支付 | N30: 肖志强
A31: 45621 | B31: null | D31: 58 | E31: 58 | F31: 41139 | G31: 万龙体验中心 | H31: 赵女士 | I31: 19535784886 | J31: 58 | L31: 0.43165509 | M31: 微信支付 | N31: 肖志强
A32: 45622 | B32: XSD20241126000I | D32: 399 | E32: 359 | F32: 41165 | G32: 万龙体验中心 | H32: 阿振 | J32: 359 | L32: 0.47530093 | M32: 现金 | N32: 布乖 | O32: 实际是微信转账提现
A33: 45624 | B33: null | D33: 4780 | E33: 3080 | F33: 41215 | G33: 崇礼旗舰店 | H33: 沁城先生 | I33: 17278866532 | J33: 3080 | L33: 0.95138889 | M33: 微信支付 | N33: 布乖
A34: 45624 | B34: XSD20241128000A | D34: 790 | E34: 474 | F34: 41204 | G34: 南山 | H34: 邢春杰先生 | I34: 18001077061 | J34: 474 | L34: 0.54810185 | M34: 现金 | O34: 实际微信转布乖
A35: 45625 | B35: null | D35: 2200 | E35: 1500 | F35: 41243 | G35: 万龙体验中心 | H35: 黄女士 | I35: 13161892380 | J35: 1500 | L35: 0.75157407 | M35: 微信支付 | N35: 布乖
A36: 45625 | B36: null | D36: 174 | E36: 174 | F36: 41218 | G36: 万龙体验中心 | J36: 174 | L36: 0.36287037 | M36: 微信支付 | N36: 肖志强
A37: 45625 | B37: 紧急开单 | D37: 58 | E37: 58 | F37: 41216 | G37: 万龙体验中心 | H37: 吕 | I37: 17542913333 | J37: 58 | L37: 0.32701389 | M37: 微信支付 | N37: (个人)张小飞
A38: 45626 | B38: XSD20241130005I | D38: 6080 | E38: 6080 | F38: 41451 | G38: 万龙体验中心 | H38: 李聪女士 | I38: 18210198199 | J38: 6080 | L38: 0.87922454 | M38: 微信支付 | N38: 布乖
A39: 45626 | B39: XSD20241130004I | D39: 8156 | E39: 7159 | F39: 41450 | G39: 崇礼旗舰店 | H39: 小A老师女士 | I39: 13806266161 | J39: 7159 | L39: 0.86989583 | M39: 现金 | N39: 布乖 | O39: 实际微信转布乖
A40: 45626 | B40: XSD20241130003A | D40: 7150 | E40: 4290 | F40: 41440 | G40: 南山 | J40: 4290 | L40: 0.74315972 | M40: 现金 | N40: 张新健
...

Sheet 万龙雪票
A1: `2024-12-19 22:26:14 | B1: `wxd1310896f2aa68bb | C1: `1636140745 | D1: `0 | E1: ` | F1: `4200002363202412196830551366 | G1: `QJ_XP_20241219_042754_ZF_01 | H1: `oHdTn5Wlwy37YA6kmJP6zE9AoTlI | I1: `JSAPI | J1: `SUCCESS | K1: `BOC_CREDIT | L1: `CNY | M1: `0.14 | N1: `0.00 | O1: `0 | P1: `0 | Q1: `0.00 | R1: `0.00 | S1: ` | T1: ` | U1: `租赁 | V1: ` | W1: `0.00000 | X1: `0.54% | Y1: 0.14 | Z1: 0
A2: `2024-12-19 22:09:30 | B2: `wxd1310896f2aa68bb | C2: `1636140745 | D2: `0 | E2: ` | F2: `4200002368202412190711419979 | G2: `QJ_XP_20241219_042748_ZF_01 | H2: `oHdTn5Wlwy37YA6kmJP6zE9AoTlI | I2: `JSAPI | J2: `SUCCESS | K2: `BOC_CREDIT | L2: `CNY | M2: `0.11 | N2: `0.00 | O2: `0 | P2: `0 | Q2: `0.00 | R2: `0.00 | S2: ` | T2: ` | U2: `租赁 | V2: ` | W2: `0.00000 | X2: `0.54% | Y2: 0.11 | Z2: 0 | AA2: `
A3: `2024-12-19 22:56:25 | B3: `wxd1310896f2aa68bb | C3: `1636140745 | D3: `0 | E3: ` | F3: `4200002370202412197726571637 | G3: `QJ_XP_20241219_042759_ZF_01 | H3: `oHdTn5Wlwy37YA6kmJP6zE9AoTlI | I3: `JSAPI | J3: `SUCCESS | K3: `BOC_CREDIT | L3: `CNY | M3: `0.08 | N3: `0.00 | O3: `0 | P3: `0 | Q3: `0.00 | R3: `0.00 | S3: ` | T3: ` | U3: `租赁 | V3: ` | W3: `0.00000 | X3: `0.54% | Y3: 0.08 | Z3: 0 | AA3: `
A4: `2024-12-19 22:39:30 | B4: `wxd1310896f2aa68bb | C4: `1636140745 | D4: `0 | E4: ` | F4: `4200002373202412194657595334 | G4: `QJ_XP_20241219_042755_ZF_01 | H4: `oHdTn5Wlwy37YA6kmJP6zE9AoTlI | I4: `JSAPI | J4: `SUCCESS | K4: `BOC_CREDIT | L4: `CNY | M4: `0.14 | N4: `0.00 | O4: `0 | P4: `0 | Q4: `0.00 | R4: `0.00 | S4: ` | T4: ` | U4: `租赁 | V4: ` | W4: `0.00000 | X4: `0.54% | Y4: 0.14 | Z4: 0 | AA4: `
A5: `2024-12-19 22:50:46 | B5: `wxd1310896f2aa68bb | C5: `1636140745 | D5: `0 | E5: ` | F5: `4200002383202412192767242960 | G5: `QJ_XP_20241219_042757_ZF_01 | H5: `oHdTn5Wlwy37YA6kmJP6zE9AoTlI | I5: `JSAPI | J5: `SUCCESS | K5: `BOC_CREDIT | L5: `CNY | M5: `0.14 | N5: `0.00 | O5: `0 | P5: `0 | Q5: `0.00 | R5: `0.00 | S5: ` | T5: ` | U5: `租赁 | V5: ` | W5: `0.00000 | X5: `0.54% | Y5: 0.14 | Z5: 0 | AA5: `
A6: `2024-12-19 22:25:27 | B6: `wxd1310896f2aa68bb | C6: `1636140745 | D6: `0 | E6: ` | F6: `4200002388202412192217351495 | G6: `QJ_XP_20241219_042753_ZF_01 | H6: `oHdTn5Wlwy37YA6kmJP6zE9AoTlI | I6: `JSAPI | J6: `SUCCESS | K6: `BOC_CREDIT | L6: `CNY | M6: `0.14 | N6: `0.00 | O6: `0 | P6: `0 | Q6: `0.00 | R6: `0.00 | S6: ` | T6: ` | U6: `租赁 | V6: ` | W6: `0.00000 | X6: `0.54% | Y6: 0.14 | Z6: 0 | AA6: `
A7: `2024-12-19 21:35:18 | B7: `wxd1310896f2aa68bb | C7: `1636140745 | D7: `0 | E7: ` | F7: `4200002388202412199699549948 | G7: `QJ_XP_20241219_042740_ZF_01 | H7: `oHdTn5Wlwy37YA6kmJP6zE9AoTlI | I7: `JSAPI | J7: `SUCCESS | K7: `BOC_CREDIT | L7: `CNY | M7: `0.11 | N7: `0.00 | O7: `0 | P7: `0 | Q7: `0.00 | R7: `0.00 | S7: ` | T7: ` | U7: `租赁 | V7: ` | W7: `0.00000 | X7: `0.54% | Y7: 0.11 | Z7: 0 | AA7: `
A8: `2024-12-19 22:19:14 | B8: `wxd1310896f2aa68bb | C8: `1636140745 | D8: `0 | E8: ` | F8: `4200002389202412198416476825 | G8: `QJ_XP_20241219_042752_ZF_01 | H8: `oHdTn5Wlwy37YA6kmJP6zE9AoTlI | I8: `JSAPI | J8: `SUCCESS | K8: `BOC_CREDIT | L8: `CNY | M8: `0.14 | N8: `0.00 | O8: `0 | P8: `0 | Q8: `0.00 | R8: `0.00 | S8: ` | T8: ` | U8: `租赁 | V8: ` | W8: `0.00000 | X8: `0.54% | Y8: 0.14 | Z8: 0 | AA8: `
A9: `2024-12-19 22:10:33 | B9: `wxd1310896f2aa68bb | C9: `1636140745 | D9: `0 | E9: ` | F9: `4200002390202412196675847654 | G9: `QJ_XP_20241219_042749_ZF_01 | H9: `oHdTn5Wlwy37YA6kmJP6zE9AoTlI | I9: `JSAPI | J9: `SUCCESS | K9: `BOC_CREDIT | L9: `CNY | M9: `0.11 | N9: `0.00 | O9: `0 | P9: `0 | Q9: `0.00 | R9: `0.00 | S9: ` | T9: ` | U9: `租赁 | V9: ` | W9: `0.00000 | X9: `0.54% | Y9: 0.11 | Z9: 0 | AA9: `
A10: `2024-12-19 21:55:21 | B10: `wxd1310896f2aa68bb | C10: `1636140745 | D10: `0 | E10: ` | F10: `4200002488202412192682570706 | G10: `QJ_XP_20241219_042747_ZF_01 | H10: `oHdTn5Wlwy37YA6kmJP6zE9AoTlI | I10: `JSAPI | J10: `SUCCESS | K10: `BOC_CREDIT | L10: `CNY | M10: `0.11 | N10: `0.00 | O10: `0 | P10: `0 | Q10: `0.00 | R10: `0.00 | S10: ` | T10: ` | U10: `租赁 | V10: ` | W10: `0.00000 | X10: `0.54% | Y10: 0.11 | Z10: 0 | AA10: `
A11: `2024-12-19 22:15:39 | B11: `wxd1310896f2aa68bb | C11: `1636140745 | D11: `0 | E11: ` | F11: `4200002489202412195356559746 | G11: `QJ_XP_20241219_042751_ZF_01 | H11: `oHdTn5Wlwy37YA6kmJP6zE9AoTlI | I11: `JSAPI | J11: `SUCCESS | K11: `BOC_CREDIT | L11: `CNY | M11: `0.14 | N11: `0.00 | O11: `0 | P11: `0 | Q11: `0.00 | R11: `0.00 | S11: ` | T11: ` | U11: `租赁 | V11: ` | W11: `0.00000 | X11: `0.54% | Y11: 0.14 | Z11: 0 | AA11: `
A12: `2024-12-19 20:14:37 | B12: `wxd1310896f2aa68bb | C12: `1636140745 | D12: `0 | E12: ` | F12: `4200002496202412195256641423 | G12: `QJ_XP_20241219_042734_ZF_01 | H12: `oHdTn5Wlwy37YA6kmJP6zE9AoTlI | I12: `JSAPI | J12: `SUCCESS | K12: `BOC_CREDIT | L12: `CNY | M12: `0.14 | N12: `0.00 | O12: `0 | P12: `0 | Q12: `0.00 | R12: `0.00 | S12: ` | T12: ` | U12: `租赁 | V12: ` | W12: `0.00000 | X12: `0.54% | Y12: 0.14 | Z12: 0 | AA12: `
A13: `2024-12-19 21:04:40 | B13: `wxd1310896f2aa68bb | C13: `1636140745 | D13: `0 | E13: ` | F13: `4200002503202412193198167017 | G13: `QJ_XP_20241219_042738_ZF_01 | H13: `oHdTn5Wlwy37YA6kmJP6zE9AoTlI | I13: `JSAPI | J13: `SUCCESS | K13: `BOC_CREDIT | L13: `CNY | M13: `0.19 | N13: `0.00 | O13: `0 | P13: `0 | Q13: `0.00 | R13: `0.00 | S13: ` | T13: ` | U13: `租赁 | V13: ` | W13: `0.00000 | X13: `0.54% | Y13: 0.19 | Z13: 0 | AA13: `
... A24: `2024-12-20 19:33:13 | B24: `wxd1310896f2aa68bb | C24: `1636140745 | D24: `0 | E24: ` | F24: `4200002388202412192217351495 | G24: `QJ_XP_20241219_042753_ZF_01 | H24: `oHdTn5Wlwy37YA6kmJP6zE9AoTlI | I24: `JSAPI | J24: `REFUND | K24: `BOC_CREDIT | L24: `CNY | M24: `0.00 | N24: `0.00 | O24: `50301501732024122009029816380 | P24: `QJ_XP_20241219_042753_ZF_01_TK_01_20241220 | Q24: `0.14 | R24: `0.00 | S24: `ORIGINAL | T24: `SUCCESS | U24: `租赁 | V24: ` | W24: `0.00000 | X24: `0.54% | Y24: 0 | Z24: 0.14 | AA24: `
A25: `2024-12-20 19:26:45 | B25: `wxd1310896f2aa68bb | C25: `1636140745 | D25: `0 | E25: ` | F25: `4200002388202412199699549948 | G25: `QJ_XP_20241219_042740_ZF_01 | H25: `oHdTn5Wlwy37YA6kmJP6zE9AoTlI | I25: `JSAPI | J25: `REFUND | K25: 44892 | L25: `CNY | M25: `0.00 | N25: `0.00 | O25: `50302801782024122065204720853 | P25: `QJ_XP_20241219_042740_ZF_01_TK_01_20241220 | Q25: `0.11 | R25: `0.00 | S25: `ORIGINAL | T25: `SUCCESS | U25: `租赁 | V25: ` | W25: `0.00000 | X25: `0.54% | Y25: 0 | Z25: 0.11 | AA25: `
A26: `2024-12-20 19:33:08 | B26: `wxd1310896f2aa68bb | C26: `1636140745 | D26: `0 | E26: ` | F26: `4200002389202412198416476825 | G26: `QJ_XP_20241219_042752_ZF_01 | H26: `oHdTn5Wlwy37YA6kmJP6zE9AoTlI | I26: `JSAPI | J26: `REFUND | K26: `BOC_CREDIT | L26: `CNY | M26: `0.00 | N26: `0.00 | O26: `50302501622024122067882619760 | P26: `QJ_XP_20241219_042752_ZF_01_TK_01_20241220 | Q26: `0.14 | R26: `0.00 | S26: `ORIGINAL | T26: `SUCCESS | U26: `租赁 | V26: ` | W26: `0.00000 | X26: `0.54% | Y26: 0 | Z26: 0.14 | AA26: `
A27: `2024-12-20 19:27:28 | B27: `wxd1310896f2aa68bb | C27: `1636140745 | D27: `0 | E27: ` | F27: `4200002390202412196675847654 | G27: `QJ_XP_20241219_042749_ZF_01 | H27: `oHdTn5Wlwy37YA6kmJP6zE9AoTlI | I27: `JSAPI | J27: `REFUND | K27: `BOC_CREDIT | L27: `CNY | M27: `0.00 | N27: `0.00 | O27: `50301401892024122057710874471 | P27: `QJ_XP_20241219_042749_ZF_01_TK_01_20241220 | Q27: `0.11 | R27: `0.00 | S27: `ORIGINAL | T27: `SUCCESS | U27: `租赁 | V27: ` | W27: `0.00000 | X27: `0.54% | Y27: 0 | Z27: 0.11 | AA27: `
